Workbook

Sheet 👥 ÉQUIPES
A1: 👥 RÉFÉRENTIEL DES ÉQUIPES SAV
A3: Définissez ici chaque équipe. Le nom d'équipe sera utilisé dans la feuille SAISIE.
B4: NOM DE L'ÉQUIPE | C4: TECHNICIEN 1 | D4: TECHNICIEN 2 | E4: DATE CRÉATION
B5: Équipe A
B6: Équipe B
B7: Équipe C
B8: Équipe D
B9: Équipe E

Sheet 📋 SAISIE
A1: 📋 SAISIE DES ÉVALUATIONS – 1 LIGNE = 1 INTERVENTION
A2: Saisissez les notes (1-5) pour chaque intervention. Le fichier calcule et parle automatiquement →
A3: IDENTIFICATION | F3: 🛠️ TERRAIN (12 critères – max 60 pts) | R3: 🧠 COMPORTEMENT (10 critères – max 50 pts) | AB3: SCORES BRUTS | AE3: RÉSULTAT | AG3: DÉCISION AUTOMATIQUE
F4: ← Notez chaque critère de 1 (insuffisant) à 5 (excellent) → | R4: ← Notez chaque critère de 1 (insuffisant) à 5 (excellent) →
A5: # | B5: Date | C5: Équipe | D5: Réf. Intervention | E5: Responsable | F5: T1 Diagnostic initial | G5: T2 Contrôle voyants | H5: T3 Lecture RX | I5: T4 Logique de panne | J5: T5 Règle 30 min | K5: T6 Prise de décision | L5: T7 Réparation / KO | M5: T8 Cohérence motif | N5: T9 Praxedo | O5: T10 TeamLink | P5: T11 Clôture | Q5: T12 Efficacité binôme | R5: C1 Rapidité réflexion | S5: C2 Logique analyse | T5: C3 Gestion du temps | U5: C4 Rigueur | V5: C5 Capacité à décider | W5: C6 Respect des règles | X5: C7 Gestion du stress | Y5: C8 Complémentarité | Z5: C9 Autonomie | AA5: C10 Posture client | AB5: Score Terrain /60 | AC5: Score Comport. /50 | AD5: Total /110 | AE5: Note /100 | AF5: Niveau A/B/C/D | AG5: 💬 DÉCISION AUTOMATIQUE | AH5: Observations
A7: 1 | AB7: =IF(COUNTA(F7:Q7)=0,"",SUM(F7:Q7)) | AC7: =IF(COUNTA(R7:AA7)=0,"",SUM(R7:AA7)) | AD7: =IF(AB7="","",IFERROR(AB7+AC7,AB7)) | AE7: =IF(AD7="","",ROUND(AD7/110*100,1)) | AF7: =IF(AE7="","",IF(AE7>=85,"A",IF(AE7>=70,"B",IF(AE7>=50,"C","D")))) | AG7: =IF(AE7="","⏳ Saisir les notes...",IF(AF7="A","🏆 EXCELLENT – "&C7&" maîtrise parfaitement. Score "&ROUND(AE7,1)&"/100. Aucune action.",IF(AF7="B","✅ BON NIVEAU – "&C7&". Score "&ROUND(AE7,1)&"/100. Suivi régulier conseillé.",IF(AF7="C","⚠️ PASSABLE – "&C7&". Score "&ROUND(AE7,1)&"/100. Formation recommandée sous 30 jours.","🚨 INSUFFISANT – "&C7&". Score "&ROUND(AE7,1)&"/100. Action corrective URGENTE.")))) -> ⏳ Saisir les notes...
A8: 2 | AB8: =IF(COUNTA(F8:Q8)=0,"",SUM(F8:Q8)) | AC8: =IF(COUNTA(R8:AA8)=0,"",SUM(R8:AA8)) | AD8: =IF(AB8="","",IFERROR(AB8+AC8,AB8)) | AE8: =IF(AD8="","",ROUND(AD8/110*100,1)) | AF8: =IF(AE8="","",IF(AE8>=85,"A",IF(AE8>=70,"B",IF(AE8>=50,"C","D")))) | AG8: =IF(AE8="","⏳ Saisir les notes...",IF(AF8="A","🏆 EXCELLENT – "&C8&" maîtrise parfaitement. Score "&ROUND(AE8,1)&"/100. Aucune action.",IF(AF8="B","✅ BON NIVEAU – "&C8&". Score "&ROUND(AE8,1)&"/100. Suivi régulier conseillé.",IF(AF8="C","⚠️ PASSABLE – "&C8&". Score "&ROUND(AE8,1)&"/100. Formation recommandée sous 30 jours.","🚨 INSUFFISANT – "&C8&". Score "&ROUND(AE8,1)&"/100. Action corrective URGENTE.")))) -> ⏳ Saisir les notes...
A9: 3 | AB9: =IF(COUNTA(F9:Q9)=0,"",SUM(F9:Q9)) | AC9: =IF(COUNTA(R9:AA9)=0,"",SUM(R9:AA9)) | AD9: =IF(AB9="","",IFERROR(AB9+AC9,AB9)) | AE9: =IF(AD9="","",ROUND(AD9/110*100,1)) | AF9: =IF(AE9="","",IF(AE9>=85,"A",IF(AE9>=70,"B",IF(AE9>=50,"C","D")))) | AG9: =IF(AE9="","⏳ Saisir les notes...",IF(AF9="A","🏆 EXCELLENT – "&C9&" maîtrise parfaitement. Score "&ROUND(AE9,1)&"/100. Aucune action.",IF(AF9="B","✅ BON NIVEAU – "&C9&". Score "&ROUND(AE9,1)&"/100. Suivi régulier conseillé.",IF(AF9="C","⚠️ PASSABLE – "&C9&". Score "&ROUND(AE9,1)&"/100. Formation recommandée sous 30 jours.","🚨 INSUFFISANT – "&C9&". Score "&ROUND(AE9,1)&"/100. Action corrective URGENTE.")))) -> ⏳ Saisir les notes...
A10: 4 | AB10: =IF(COUNTA(F10:Q10)=0,"",SUM(F10:Q10)) | AC10: =IF(COUNTA(R10:AA10)=0,"",SUM(R10:AA10)) | AD10: =IF(AB10="","",IFERROR(AB10+AC10,AB10)) | AE10: =IF(AD10="","",ROUND(AD10/110*100,1)) | AF10: =IF(AE10="","",IF(AE10>=85,"A",IF(AE10>=70,"B",IF(AE10>=50,"C","D")))) | AG10: =IF(AE10="","⏳ Saisir les notes...",IF(AF10="A","🏆 EXCELLENT – "&C10&" maîtrise parfaitement. Score "&ROUND(AE10,1)&"/100. Aucune action.",IF(AF10="B","✅ BON NIVEAU – "&C10&". Score "&ROUND(AE10,1)&"/100. Suivi régulier conseillé.",IF(AF10="C","⚠️ PASSABLE – "&C10&". Score "&ROUND(AE10,1)&"/100. Formation recommandée sous 30 jours.","🚨 INSUFFISANT – "&C10&". Score "&ROUND(AE10,1)&"/100. Action corrective URGENTE.")))) -> ⏳ Saisir les notes...
A11: 5 | AB11: =IF(COUNTA(F11:Q11)=0,"",SUM(F11:Q11)) | AC11: =IF(COUNTA(R11:AA11)=0,"",SUM(R11:AA11)) | AD11: =IF(AB11="","",IFERROR(AB11+AC11,AB11)) | AE11: =IF(AD11="","",ROUND(AD11/110*100,1)) | AF11: =IF(AE11="","",IF(AE11>=85,"A",IF(AE11>=70,"B",IF(AE11>=50,"C","D")))) | AG11: =IF(AE11="","⏳ Saisir les notes...",IF(AF11="A","🏆 EXCELLENT – "&C11&" maîtrise parfaitement. Score "&ROUND(AE11,1)&"/100. Aucune action.",IF(AF11="B","✅ BON NIVEAU – "&C11&". Score "&ROUND(AE11,1)&"/100. Suivi régulier conseillé.",IF(AF11="C","⚠️ PASSABLE – "&C11&". Score "&ROUND(AE11,1)&"/100. Formation recommandée sous 30 jours.","🚨 INSUFFISANT – "&C11&". Score "&ROUND(AE11,1)&"/100. Action corrective URGENTE.")))) -> ⏳ Saisir les notes...
A12: 6 | AB12: =IF(COUNTA(F12:Q12)=0,"",SUM(F12:Q12)) | AC12: =IF(COUNTA(R12:AA12)=0,"",SUM(R12:AA12)) | AD12: =IF(AB12="","",IFERROR(AB12+AC12,AB12)) | AE12: =IF(AD12="","",ROUND(AD12/110*100,1)) | AF12: =IF(AE12="","",IF(AE12>=85,"A",IF(AE12>=70,"B",IF(AE12>=50,"C","D")))) | AG12: =IF(AE12="","⏳ Saisir les notes...",IF(AF12="A","🏆 EXCELLENT – "&C12&" maîtrise parfaitement. Score "&ROUND(AE12,1)&"/100. Aucune action.",IF(AF12="B","✅ BON NIVEAU – "&C12&". Score "&ROUND(AE12,1)&"/100. Suivi régulier conseillé.",IF(AF12="C","⚠️ PASSABLE – "&C12&". Score "&ROUND(AE12,1)&"/100. Formation recommandée sous 30 jours.","🚨 INSUFFISANT – "&C12&". Score "&ROUND(AE12,1)&"/100. Action corrective URGENTE.")))) -> ⏳ Saisir les notes...
A13: 7 | AB13: =IF(COUNTA(F13:Q13)=0,"",SUM(F13:Q13)) | AC13: =IF(COUNTA(R13:AA13)=0,"",SUM(R13:AA13)) | AD13: =IF(AB13="","",IFERROR(AB13+AC13,AB13)) | AE13: =IF(AD13="","",ROUND(AD13/110*100,1)) | AF13: =IF(AE13="","",IF(AE13>=85,"A",IF(AE13>=70,"B",IF(AE13>=50,"C","D")))) | AG13: =IF(AE13="","⏳ Saisir les notes...",IF(AF13="A","🏆 EXCELLENT – "&C13&" maîtrise parfaitement. Score "&ROUND(AE13,1)&"/100. Aucune action.",IF(AF13="B","✅ BON NIVEAU – "&C13&". Score "&ROUND(AE13,1)&"/100. Suivi régulier conseillé.",IF(AF13="C","⚠️ PASSABLE – "&C13&". Score "&ROUND(AE13,1)&"/100. Formation recommandée sous 30 jours.","🚨 INSUFFISANT – "&C13&". Score "&ROUND(AE13,1)&"/100. Action corrective URGENTE.")))) -> ⏳ Saisir les notes...
A14: 8 | AB14: =IF(COUNTA(F14:Q14)=0,"",SUM(F14:Q14)) | AC14: =IF(COUNTA(R14:AA14)=0,"",SUM(R14:AA14)) | AD14: =IF(AB14="","",IFERROR(AB14+AC14,AB14)) | AE14: =IF(AD14="","",ROUND(AD14/110*100,1)) | AF14: =IF(AE14="","",IF(AE14>=85,"A",IF(AE14>=70,"B",IF(AE14>=50,"C","D")))) | AG14: =IF(AE14="","⏳ Saisir les notes...",IF(AF14="A","🏆 EXCELLENT – "&C14&" maîtrise parfaitement. Score "&ROUND(AE14,1)&"/100. Aucune action.",IF(AF14="B","✅ BON NIVEAU – "&C14&". Score "&ROUND(AE14,1)&"/100. Suivi régulier conseillé.",IF(AF14="C","⚠️ PASSABLE – "&C14&". Score "&ROUND(AE14,1)&"/100. Formation recommandée sous 30 jours.","🚨 INSUFFISANT – "&C14&". Score "&ROUND(AE14,1)&"/100. Action corrective URGENTE.")))) -> ⏳ Saisir les notes...
A15: 9 | AB15: =IF(COUNTA(F15:Q15)=0,"",SUM(F15:Q15)) | AC15: =IF(COUNTA(R15:AA15)=0,"",SUM(R15:AA15)) | AD15: =IF(AB15="","",IFERROR(AB15+AC15,AB15)) | AE15: =IF(AD15="","",ROUND(AD15/110*100,1)) | AF15: =IF(AE15="","",IF(AE15>=85,"A",IF(AE15>=70,"B",IF(AE15>=50,"C","D")))) | AG15: =IF(AE15="","⏳ Saisir les notes...",IF(AF15="A","🏆 EXCELLENT – "&C15&" maîtrise parfaitement. Score "&ROUND(AE15,1)&"/100. Aucune action.",IF(AF15="B","✅ BON NIVEAU – "&C15&". Score "&ROUND(AE15,1)&"/100. Suivi régulier conseillé.",IF(AF15="C","⚠️ PASSABLE – "&C15&". Score "&ROUND(AE15,1)&"/100. Formation recommandée sous 30 jours.","🚨 INSUFFISANT – "&C15&". Score "&ROUND(AE15,1)&"/100. Action corrective URGENTE.")))) -> ⏳ Saisir les notes...
A16: 10 | AB16: =IF(COUNTA(F16:Q16)=0,"",SUM(F16:Q16)) | AC16: =IF(COUNTA(R16:AA16)=0,"",SUM(R16:AA16)) | AD16: =IF(AB16="","",IFERROR(AB16+AC16,AB16)) | AE16: =IF(AD16="","",ROUND(AD16/110*100,1)) | AF16: =IF(AE16="","",IF(AE16>=85,"A",IF(AE16>=70,"B",IF(AE16>=50,"C","D")))) | AG16: =IF(AE16="","⏳ Saisir les notes...",IF(AF16="A","🏆 EXCELLENT – "&C16&" maîtrise parfaitement. Score "&ROUND(AE16,1)&"/100. Aucune action.",IF(AF16="B","✅ BON NIVEAU – "&C16&". Score "&ROUND(AE16,1)&"/100. Suivi régulier conseillé.",IF(AF16="C","⚠️ PASSABLE – "&C16&". Score "&ROUND(AE16,1)&"/100. Formation recommandée sous 30 jours.","🚨 INSUFFISANT – "&C16&". Score "&ROUND(AE16,1)&"/100. Action corrective URGENTE.")))) -> ⏳ Saisir les notes...
A17: 11 | AB17: =IF(COUNTA(F17:Q17)=0,"",SUM(F17:Q17)) | AC17: =IF(COUNTA(R17:AA17)=0,"",SUM(R17:AA17)) | AD17: =IF(AB17="","",IFERROR(AB17+AC17,AB17)) | AE17: =IF(AD17="","",ROUND(AD17/110*100,1)) | AF17: =IF(AE17="","",IF(AE17>=85,"A",IF(AE17>=70,"B",IF(AE17>=50,"C","D")))) | AG17: =IF(AE17="","⏳ Saisir les notes...",IF(AF17="A","🏆 EXCELLENT – "&C17&" maîtrise parfaitement. Score "&ROUND(AE17,1)&"/100. Aucune action.",IF(AF17="B","✅ BON NIVEAU – "&C17&". Score "&ROUND(AE17,1)&"/100. Suivi régulier conseillé.",IF(AF17="C","⚠️ PASSABLE – "&C17&". Score "&ROUND(AE17,1)&"/100. Formation recommandée sous 30 jours.","🚨 INSUFFISANT – "&C17&". Score "&ROUND(AE17,1)&"/100. Action corrective URGENTE.")))) -> ⏳ Saisir les notes...
A18: 12 | AB18: =IF(COUNTA(F18:Q18)=0,"",SUM(F18:Q18)) | AC18: =IF(COUNTA(R18:AA18)=0,"",SUM(R18:AA18)) | AD18: =IF(AB18="","",IFERROR(AB18+AC18,AB18)) | AE18: =IF(AD18="","",ROUND(AD18/110*100,1)) | AF18: =IF(AE18="","",IF(AE18>=85,"A",IF(AE18>=70,"B",IF(AE18>=50,"C","D")))) | AG18: =IF(AE18="","⏳ Saisir les notes...",IF(AF18="A","🏆 EXCELLENT – "&C18&" maîtrise parfaitement. Score "&ROUND(AE18,1)&"/100. Aucune action.",IF(AF18="B","✅ BON NIVEAU – "&C18&". Score "&ROUND(AE18,1)&"/100. Suivi régulier conseillé.",IF(AF18="C","⚠️ PASSABLE – "&C18&". Score "&ROUND(AE18,1)&"/100. Formation recommandée sous 30 jours.","🚨 INSUFFISANT – "&C18&". Score "&ROUND(AE18,1)&"/100. Action corrective URGENTE.")))) -> ⏳ Saisir les notes...
... A56: 50 | AB56: =IF(COUNTA(F56:Q56)=0,"",SUM(F56:Q56)) | AC56: =IF(COUNTA(R56:AA56)=0,"",SUM(R56:AA56)) | AD56: =IF(AB56="","",IFERROR(AB56+AC56,AB56)) | AE56: =IF(AD56="","",ROUND(AD56/110*100,1)) | AF56: =IF(AE56="","",IF(AE56>=85,"A",IF(AE56>=70,"B",IF(AE56>=50,"C","D")))) | AG56: =IF(AE56="","⏳ Saisir les notes...",IF(AF56="A","🏆 EXCELLENT – "&C56&" maîtrise parfaitement. Score "&ROUND(AE56,1)&"/100. Aucune action.",IF(AF56="B","✅ BON NIVEAU – "&C56&". Score "&ROUND(AE56,1)&"/100. Suivi régulier conseillé.",IF(AF56="C","⚠️ PASSABLE – "&C56&". Score "&ROUND(AE56,1)&"/100. Formation recommandée sous 30 jours.","🚨 INSUFFISANT – "&C56&". Score "&ROUND(AE56,1)&"/100. Action corrective URGENTE.")))) -> ⏳ Saisir les notes...

Sheet 📊 TABLEAU DE BORD
A1: 📊 TABLEAU DE BORD – SUIVI PAR ÉQUIPE (TOUTES INTERVENTIONS)
A2: Ce tableau agrège automatiquement toutes les interventions saisies, par équipe. Filtrez par date dans la feuille SAISIE si besoin.
A4: ℹ️ Les indicateurs ci-dessous se mettent à jour automatiquement dès que vous saisissez des notes dans 📋 SAISIE
B6: ÉQUIPE | C6: Nb Interventions évaluées | D6: Moy. Terrain /60 | E6: Moy. Comport. /50 | F6: Moy. Totale /110 | G6: Note Moy. /100 | H6: Niveau Moyen | I6: 💬 VERDICT ÉQUIPE AUTOMATIQUE
B7: ='👥 ÉQUIPES'!$B$5 -> Équipe A | C7: =COUNTIF('📋 SAISIE'!$C$7:$C$56,'👥 ÉQUIPES'!$B$5) -> 0 | D7: =IFERROR(ROUND(AVERAGEIF('📋 SAISIE'!$C$7:$C$56,'👥 ÉQUIPES'!$B$5,'📋 SAISIE'!$AB$7:$AB$56),1),"—") -> — | E7: =IFERROR(ROUND(AVERAGEIF('📋 SAISIE'!$C$7:$C$56,'👥 ÉQUIPES'!$B$5,'📋 SAISIE'!$AC$7:$AC$56),1),"—") -> — | F7: =IFERROR(ROUND(AVERAGEIF('📋 SAISIE'!$C$7:$C$56,'👥 ÉQUIPES'!$B$5,'📋 SAISIE'!$AD$7:$AD$56),1),"—") -> — | G7: =IFERROR(ROUND(AVERAGEIF('📋 SAISIE'!$C$7:$C$56,'👥 ÉQUIPES'!$B$5,'📋 SAISIE'!$AE$7:$AE$56),1),"—") -> — | H7: =IF(C7=0,"—",IF(G7>=85,"A",IF(G7>=70,"B",IF(G7>=50,"C","D")))) -> — | I7: =IF(C7=0,"⏳ Aucune intervention saisie pour cette équipe.",IF(G7>=85,"🏆 EXCELLENT – "&B7&" : "&C7&" intervention(s) – Moyenne "&ROUND(G7,1)&"/100. Équipe au top, maintenir le rythme !",IF(G7>=70,"✅ BON NIVEAU – "&B7&" : "&C7&" intervention(s) – Moyenne "&ROUND(G7,1)&"/100. Bon travail, axes d'amélioration ciblés.",IF(G7>=50,"⚠️ PASSABLE – "&B7&" : "&C7&" intervention(s) – Moyenne "&ROUND(G7,1)&"/100. Formation recommandée. Accompagnement renforcé nécessaire.","🚨 INSUFFISANT – "&B7&" : "&C7&" intervention(s) – Moyenne "&ROUND(G7,1)&"/100. Remise à niveau URGENTE. Plan d'action immédiat.")))) -> ⏳ Aucune intervention saisie pour cette équipe.
B8: ='👥 ÉQUIPES'!$B$6 -> Équipe B | C8: =COUNTIF('📋 SAISIE'!$C$7:$C$56,'👥 ÉQUIPES'!$B$6) -> 0 | D8: =IFERROR(ROUND(AVERAGEIF('📋 SAISIE'!$C$7:$C$56,'👥 ÉQUIPES'!$B$6,'📋 SAISIE'!$AB$7:$AB$56),1),"—") -> — | E8: =IFERROR(ROUND(AVERAGEIF('📋 SAISIE'!$C$7:$C$56,'👥 ÉQUIPES'!$B$6,'📋 SAISIE'!$AC$7:$AC$56),1),"—") -> — | F8: =IFERROR(ROUND(AVERAGEIF('📋 SAISIE'!$C$7:$C$56,'👥 ÉQUIPES'!$B$6,'📋 SAISIE'!$AD$7:$AD$56),1),"—") -> — | G8: =IFERROR(ROUND(AVERAGEIF('📋 SAISIE'!$C$7:$C$56,'👥 ÉQUIPES'!$B$6,'📋 SAISIE'!$AE$7:$AE$56),1),"—") -> — | H8: =IF(C8=0,"—",IF(G8>=85,"A",IF(G8>=70,"B",IF(G8>=50,"C","D")))) -> — | I8: =IF(C8=0,"⏳ Aucune intervention saisie pour cette équipe.",IF(G8>=85,"🏆 EXCELLENT – "&B8&" : "&C8&" intervention(s) – Moyenne "&ROUND(G8,1)&"/100. Équipe au top, maintenir le rythme !",IF(G8>=70,"✅ BON NIVEAU – "&B8&" : "&C8&" intervention(s) – Moyenne "&ROUND(G8,1)&"/100. Bon travail, axes d'amélioration ciblés.",IF(G8>=50,"⚠️ PASSABLE – "&B8&" : "&C8&" intervention(s) – Moyenne "&ROUND(G8,1)&"/100. Formation recommandée. Accompagnement renforcé nécessaire.","🚨 INSUFFISANT – "&B8&" : "&C8&" intervention(s) – Moyenne "&ROUND(G8,1)&"/100. Remise à niveau URGENTE. Plan d'action immédiat.")))) -> ⏳ Aucune intervention saisie pour cette équipe.
B9: ='👥 ÉQUIPES'!$B$7 -> Équipe C | C9: =COUNTIF('📋 SAISIE'!$C$7:$C$56,'👥 ÉQUIPES'!$B$7) -> 0 | D9: =IFERROR(ROUND(AVERAGEIF('📋 SAISIE'!$C$7:$C$56,'👥 ÉQUIPES'!$B$7,'📋 SAISIE'!$AB$7:$AB$56),1),"—") -> — | E9: =IFERROR(ROUND(AVERAGEIF('📋 SAISIE'!$C$7:$C$56,'👥 ÉQUIPES'!$B$7,'📋 SAISIE'!$AC$7:$AC$56),1),"—") -> — | F9: =IFERROR(ROUND(AVERAGEIF('📋 SAISIE'!$C$7:$C$56,'👥 ÉQUIPES'!$B$7,'📋 SAISIE'!$AD$7:$AD$56),1),"—") -> — | G9: =IFERROR(ROUND(AVERAGEIF('📋 SAISIE'!$C$7:$C$56,'👥 ÉQUIPES'!$B$7,'📋 SAISIE'!$AE$7:$AE$56),1),"—") -> — | H9: =IF(C9=0,"—",IF(G9>=85,"A",IF(G9>=70,"B",IF(G9>=50,"C","D")))) -> — | I9: =IF(C9=0,"⏳ Aucune intervention saisie pour cette équipe.",IF(G9>=85,"🏆 EXCELLENT – "&B9&" : "&C9&" intervention(s) – Moyenne "&ROUND(G9,1)&"/100. Équipe au top, maintenir le rythme !",IF(G9>=70,"✅ BON NIVEAU – "&B9&" : "&C9&" intervention(s) – Moyenne "&ROUND(G9,1)&"/100. Bon travail, axes d'amélioration ciblés.",IF(G9>=50,"⚠️ PASSABLE – "&B9&" : "&C9&" intervention(s) – Moyenne "&ROUND(G9,1)&"/100. Formation recommandée. Accompagnement renforcé nécessaire.","🚨 INSUFFISANT – "&B9&" : "&C9&" intervention(s) – Moyenne "&ROUND(G9,1)&"/100. Remise à niveau URGENTE. Plan d'action immédiat.")))) -> ⏳ Aucune intervention saisie pour cette équipe.
B10: ='👥 ÉQUIPES'!$B$8 -> Équipe D | C10: =COUNTIF('📋 SAISIE'!$C$7:$C$56,'👥 ÉQUIPES'!$B$8) -> 0 | D10: =IFERROR(ROUND(AVERAGEIF('📋 SAISIE'!$C$7:$C$56,'👥 ÉQUIPES'!$B$8,'📋 SAISIE'!$AB$7:$AB$56),1),"—") -> — | E10: =IFERROR(ROUND(AVERAGEIF('📋 SAISIE'!$C$7:$C$56,'👥 ÉQUIPES'!$B$8,'📋 SAISIE'!$AC$7:$AC$56),1),"—") -> — | F10: =IFERROR(ROUND(AVERAGEIF('📋 SAISIE'!$C$7:$C$56,'👥 ÉQUIPES'!$B$8,'📋 SAISIE'!$AD$7:$AD$56),1),"—") -> — | G10: =IFERROR(ROUND(AVERAGEIF('📋 SAISIE'!$C$7:$C$56,'👥 ÉQUIPES'!$B$8,'📋 SAISIE'!$AE$7:$AE$56),1),"—") -> — | H10: =IF(C10=0,"—",IF(G10>=85,"A",IF(G10>=70,"B",IF(G10>=50,"C","D")))) -> — | I10: =IF(C10=0,"⏳ Aucune intervention saisie pour cette équipe.",IF(G10>=85,"🏆 EXCELLENT – "&B10&" : "&C10&" intervention(s) – Moyenne "&ROUND(G10,1)&"/100. Équipe au top, maintenir le rythme !",IF(G10>=70,"✅ BON NIVEAU – "&B10&" : "&C10&" intervention(s) – Moyenne "&ROUND(G10,1)&"/100. Bon travail, axes d'amélioration ciblés.",IF(G10>=50,"⚠️ PASSABLE – "&B10&" : "&C10&" intervention(s) – Moyenne "&ROUND(G10,1)&"/100. Formation recommandée. Accompagnement renforcé nécessaire.","🚨 INSUFFISANT – "&B10&" : "&C10&" intervention(s) – Moyenne "&ROUND(G10,1)&"/100. Remise à niveau URGENTE. Plan d'action immédiat.")))) -> ⏳ Aucune intervention saisie pour cette équipe.
B11: ='👥 ÉQUIPES'!$B$9 -> Équipe E | C11: =COUNTIF('📋 SAISIE'!$C$7:$C$56,'👥 ÉQUIPES'!$B$9) -> 0 | D11: =IFERROR(ROUND(AVERAGEIF('📋 SAISIE'!$C$7:$C$56,'👥 ÉQUIPES'!$B$9,'📋 SAISIE'!$AB$7:$AB$56),1),"—") -> — | E11: =IFERROR(ROUND(AVERAGEIF('📋 SAISIE'!$C$7:$C$56,'👥 ÉQUIPES'!$B$9,'📋 SAISIE'!$AC$7:$AC$56),1),"—") -> — | F11: =IFERROR(ROUND(AVERAGEIF('📋 SAISIE'!$C$7:$C$56,'👥 ÉQUIPES'!$B$9,'📋 SAISIE'!$AD$7:$AD$56),1),"—") -> — | G11: =IFERROR(ROUND(AVERAGEIF('📋 SAISIE'!$C$7:$C$56,'👥 ÉQUIPES'!$B$9,'📋 SAISIE'!$AE$7:$AE$56),1),"—") -> — | H11: =IF(C11=0,"—",IF(G11>=85,"A",IF(G11>=70,"B",IF(G11>=50,"C","D")))) -> — | I11: =IF(C11=0,"⏳ Aucune intervention saisie pour cette équipe.",IF(G11>=85,"🏆 EXCELLENT – "&B11&" : "&C11&" intervention(s) – Moyenne "&ROUND(G11,1)&"/100. Équipe au top, maintenir le rythme !",IF(G11>=70,"✅ BON NIVEAU – "&B11&" : "&C11&" intervention(s) – Moyenne "&ROUND(G11,1)&"/100. Bon travail, axes d'amélioration ciblés.",IF(G11>=50,"⚠️ PASSABLE – "&B11&" : "&C11&" intervention(s) – Moyenne "&ROUND(G11,1)&"/100. Formation recommandée. Accompagnement renforcé nécessaire.","🚨 INSUFFISANT – "&B11&" : "&C11&" intervention(s) – Moyenne "&ROUND(G11,1)&"/100. Remise à niveau URGENTE. Plan d'action immédiat.")))) -> ⏳ Aucune intervention saisie pour cette équipe.
B12: ='👥 ÉQUIPES'!$B$10 -> 0 | C12: =COUNTIF('📋 SAISIE'!$C$7:$C$56,'👥 ÉQUIPES'!$B$10) -> 0 | D12: =IFERROR(ROUND(AVERAGEIF('📋 SAISIE'!$C$7:$C$56,'👥 ÉQUIPES'!$B$10,'📋 SAISIE'!$AB$7:$AB$56),1),"—") -> — | E12: =IFERROR(ROUND(AVERAGEIF('📋 SAISIE'!$C$7:$C$56,'👥 ÉQUIPES'!$B$10,'📋 SAISIE'!$AC$7:$AC$56),1),"—") -> — | F12: =IFERROR(ROUND(AVERAGEIF('📋 SAISIE'!$C$7:$C$56,'👥 ÉQUIPES'!$B$10,'📋 SAISIE'!$AD$7:$AD$56),1),"—") -> — | G12: =IFERROR(ROUND(AVERAGEIF('📋 SAISIE'!$C$7:$C$56,'👥 ÉQUIPES'!$B$10,'📋 SAISIE'!$AE$7:$AE$56),1),"—") -> — | H12: =IF(C12=0,"—",IF(G12>=85,"A",IF(G12>=70,"B",IF(G12>=50,"C","D")))) -> — | I12: =IF(C12=0,"⏳ Aucune intervention saisie pour cette équipe.",IF(G12>=85,"🏆 EXCELLENT – "&B12&" : "&C12&" intervention(s) – Moyenne "&ROUND(G12,1)&"/100. Équipe au top, maintenir le rythme !",IF(G12>=70,"✅ BON NIVEAU – "&B12&" : "&C12&" intervention(s) – Moyenne "&ROUND(G12,1)&"/100. Bon travail, axes d'amélioration ciblés.",IF(G12>=50,"⚠️ PASSABLE – "&B12&" : "&C12&" intervention(s) – Moyenne "&ROUND(G12,1)&"/100. Formation recommandée. Accompagnement renforcé nécessaire.","🚨 INSUFFISANT – "&B12&" : "&C12&" intervention(s) – Moyenne "&ROUND(G12,1)&"/100. Remise à niveau URGENTE. Plan d'action immédiat.")))) -> ⏳ Aucune intervention saisie pour cette équipe.
B13: ='👥 ÉQUIPES'!$B$11 -> 0 | C13: =COUNTIF('📋 SAISIE'!$C$7:$C$56,'👥 ÉQUIPES'!$B$11) -> 0 | D13: =IFERROR(ROUND(AVERAGEIF('📋 SAISIE'!$C$7:$C$56,'👥 ÉQUIPES'!$B$11,'📋 SAISIE'!$AB$7:$AB$56),1),"—") -> — | E13: =IFERROR(ROUND(AVERAGEIF('📋 SAISIE'!$C$7:$C$56,'👥 ÉQUIPES'!$B$11,'📋 SAISIE'!$AC$7:$AC$56),1),"—") -> — | F13: =IFERROR(ROUND(AVERAGEIF('📋 SAISIE'!$C$7:$C$56,'👥 ÉQUIPES'!$B$11,'📋 SAISIE'!$AD$7:$AD$56),1),"—") -> — | G13: =IFERROR(ROUND(AVERAGEIF('📋 SAISIE'!$C$7:$C$56,'👥 ÉQUIPES'!$B$11,'📋 SAISIE'!$AE$7:$AE$56),1),"—") -> — | H13: =IF(C13=0,"—",IF(G13>=85,"A",IF(G13>=70,"B",IF(G13>=50,"C","D")))) -> — | I13: =IF(C13=0,"⏳ Aucune intervention saisie pour cette équipe.",IF(G13>=85,"🏆 EXCELLENT – "&B13&" : "&C13&" intervention(s) – Moyenne "&ROUND(G13,1)&"/100. Équipe au top, maintenir le rythme !",IF(G13>=70,"✅ BON NIVEAU – "&B13&" : "&C13&" intervention(s) – Moyenne "&ROUND(G13,1)&"/100. Bon travail, axes d'amélioration ciblés.",IF(G13>=50,"⚠️ PASSABLE – "&B13&" : "&C13&" intervention(s) – Moyenne "&ROUND(G13,1)&"/100. Formation recommandée. Accompagnement renforcé nécessaire.","🚨 INSUFFISANT – "&B13&" : "&C13&" intervention(s) – Moyenne "&ROUND(G13,1)&"/100. Remise à niveau URGENTE. Plan d'action immédiat.")))) -> ⏳ Aucune intervention saisie pour cette équipe.
B14: ='👥 ÉQUIPES'!$B$12 -> 0 | C14: =COUNTIF('📋 SAISIE'!$C$7:$C$56,'👥 ÉQUIPES'!$B$12) -> 0 | D14: =IFERROR(ROUND(AVERAGEIF('📋 SAISIE'!$C$7:$C$56,'👥 ÉQUIPES'!$B$12,'📋 SAISIE'!$AB$7:$AB$56),1),"—") -> — | E14: =IFERROR(ROUND(AVERAGEIF('📋 SAISIE'!$C$7:$C$56,'👥 ÉQUIPES'!$B$12,'📋 SAISIE'!$AC$7:$AC$56),1),"—") -> — | F14: =IFERROR(ROUND(AVERAGEIF('📋 SAISIE'!$C$7:$C$56,'👥 ÉQUIPES'!$B$12,'📋 SAISIE'!$AD$7:$AD$56),1),"—") -> — | G14: =IFERROR(ROUND(AVERAGEIF('📋 SAISIE'!$C$7:$C$56,'👥 ÉQUIPES'!$B$12,'📋 SAISIE'!$AE$7:$AE$56),1),"—") -> — | H14: =IF(C14=0,"—",IF(G14>=85,"A",IF(G14>=70,"B",IF(G14>=50,"C","D")))) -> — | I14: =IF(C14=0,"⏳ Aucune intervention saisie pour cette équipe.",IF(G14>=85,"🏆 EXCELLENT – "&B14&" : "&C14&" intervention(s) – Moyenne "&ROUND(G14,1)&"/100. Équipe au top, maintenir le rythme !",IF(G14>=70,"✅ BON NIVEAU – "&B14&" : "&C14&" intervention(s) – Moyenne "&ROUND(G14,1)&"/100. Bon travail, axes d'amélioration ciblés.",IF(G14>=50,"⚠️ PASSABLE – "&B14&" : "&C14&" intervention(s) – Moyenne "&ROUND(G14,1)&"/100. Formation recommandée. Accompagnement renforcé nécessaire.","🚨 INSUFFISANT – "&B14&" : "&C14&" intervention(s) – Moyenne "&ROUND(G14,1)&"/100. Remise à niveau URGENTE. Plan d'action immédiat.")))) -> ⏳ Aucune intervention saisie pour cette équipe.
B15: ='👥 ÉQUIPES'!$B$13 -> 0 | C15: =COUNTIF('📋 SAISIE'!$C$7:$C$56,'👥 ÉQUIPES'!$B$13) -> 0 | D15: =IFERROR(ROUND(AVERAGEIF('📋 SAISIE'!$C$7:$C$56,'👥 ÉQUIPES'!$B$13,'📋 SAISIE'!$AB$7:$AB$56),1),"—") -> — | E15: =IFERROR(ROUND(AVERAGEIF('📋 SAISIE'!$C$7:$C$56,'👥 ÉQUIPES'!$B$13,'📋 SAISIE'!$AC$7:$AC$56),1),"—") -> — | F15: =IFERROR(ROUND(AVERAGEIF('📋 SAISIE'!$C$7:$C$56,'👥 ÉQUIPES'!$B$13,'📋 SAISIE'!$AD$7:$AD$56),1),"—") -> — | G15: =IFERROR(ROUND(AVERAGEIF('📋 SAISIE'!$C$7:$C$56,'👥 ÉQUIPES'!$B$13,'📋 SAISIE'!$AE$7:$AE$56),1),"—") -> — | H15: =IF(C15=0,"—",IF(G15>=85,"A",IF(G15>=70,"B",IF(G15>=50,"C","D")))) -> — | I15: =IF(C15=0,"⏳ Aucune intervention saisie pour cette équipe.",IF(G15>=85,"🏆 EXCELLENT – "&B15&" : "&C15&" intervention(s) – Moyenne "&ROUND(G15,1)&"/100. Équipe au top, maintenir le rythme !",IF(G15>=70,"✅ BON NIVEAU – "&B15&" : "&C15&" intervention(s) – Moyenne "&ROUND(G15,1)&"/100. Bon travail, axes d'amélioration ciblés.",IF(G15>=50,"⚠️ PASSABLE – "&B15&" : "&C15&" intervention(s) – Moyenne "&ROUND(G15,1)&"/100. Formation recommandée. Accompagnement renforcé nécessaire.","🚨 INSUFFISANT – "&B15&" : "&C15&" intervention(s) – Moyenne "&ROUND(G15,1)&"/100. Remise à niveau URGENTE. Plan d'action immédiat.")))) -> ⏳ Aucune intervention saisie pour cette équipe.
B16: ='👥 ÉQUIPES'!$B$14 -> 0 | C16: =COUNTIF('📋 SAISIE'!$C$7:$C$56,'👥 ÉQUIPES'!$B$14) -> 0 | D16: =IFERROR(ROUND(AVERAGEIF('📋 SAISIE'!$C$7:$C$56,'👥 ÉQUIPES'!$B$14,'📋 SAISIE'!$AB$7:$AB$56),1),"—") -> — | E16: =IFERROR(ROUND(AVERAGEIF('📋 SAISIE'!$C$7:$C$56,'👥 ÉQUIPES'!$B$14,'📋 SAISIE'!$AC$7:$AC$56),1),"—") -> — | F16: =IFERROR(ROUND(AVERAGEIF('📋 SAISIE'!$C$7:$C$56,'👥 ÉQUIPES'!$B$14,'📋 SAISIE'!$AD$7:$AD$56),1),"—") -> — | G16: =IFERROR(ROUND(AVERAGEIF('📋 SAISIE'!$C$7:$C$56,'👥 ÉQUIPES'!$B$14,'📋 SAISIE'!$AE$7:$AE$56),1),"—") -> — | H16: =IF(C16=0,"—",IF(G16>=85,"A",IF(G16>=70,"B",IF(G16>=50,"C","D")))) -> — | I16: =IF(C16=0,"⏳ Aucune intervention saisie pour cette équipe.",IF(G16>=85,"🏆 EXCELLENT – "&B16&" : "&C16&" intervention(s) – Moyenne "&ROUND(G16,1)&"/100. Équipe au top, maintenir le rythme !",IF(G16>=70,"✅ BON NIVEAU – "&B16&" : "&C16&" intervention(s) – Moyenne "&ROUND(G16,1)&"/100. Bon travail, axes d'amélioration ciblés.",IF(G16>=50,"⚠️ PASSABLE – "&B16&" : "&C16&" intervention(s) – Moyenne "&ROUND(G16,1)&"/100. Formation recommandée. Accompagnement renforcé nécessaire.","🚨 INSUFFISANT – "&B16&" : "&C16&" intervention(s) – Moyenne "&ROUND(G16,1)&"/100. Remise à niveau URGENTE. Plan d'action immédiat.")))) -> ⏳ Aucune intervention saisie pour cette équipe.
B17: ='👥 ÉQUIPES'!$B$15 -> 0 | C17: =COUNTIF('📋 SAISIE'!$C$7:$C$56,'👥 ÉQUIPES'!$B$15) -> 0 | D17: =IFERROR(ROUND(AVERAGEIF('📋 SAISIE'!$C$7:$C$56,'👥 ÉQUIPES'!$B$15,'📋 SAISIE'!$AB$7:$AB$56),1),"—") -> — | E17: =IFERROR(ROUND(AVERAGEIF('📋 SAISIE'!$C$7:$C$56,'👥 ÉQUIPES'!$B$15,'📋 SAISIE'!$AC$7:$AC$56),1),"—") -> — | F17: =IFERROR(ROUND(AVERAGEIF('📋 SAISIE'!$C$7:$C$56,'👥 ÉQUIPES'!$B$15,'📋 SAISIE'!$AD$7:$AD$56),1),"—") -> — | G17: =IFERROR(ROUND(AVERAGEIF('📋 SAISIE'!$C$7:$C$56,'👥 ÉQUIPES'!$B$15,'📋 SAISIE'!$AE$7:$AE$56),1),"—") -> — | H17: =IF(C17=0,"—",IF(G17>=85,"A",IF(G17>=70,"B",IF(G17>=50,"C","D")))) -> — | I17: =IF(C17=0,"⏳ Aucune intervention saisie pour cette équipe.",IF(G17>=85,"🏆 EXCELLENT – "&B17&" : "&C17&" intervention(s) – Moyenne "&ROUND(G17,1)&"/100. Équipe au top, maintenir le rythme !",IF(G17>=70,"✅ BON NIVEAU – "&B17&" : "&C17&" intervention(s) – Moyenne "&ROUND(G17,1)&"/100. Bon travail, axes d'amélioration ciblés.",IF(G17>=50,"⚠️ PASSABLE – "&B17&" : "&C17&" intervention(s) – Moyenne "&ROUND(G17,1)&"/100. Formation recommandée. Accompagnement renforcé nécessaire.","🚨 INSUFFISANT – "&B17&" : "&C17&" intervention(s) – Moyenne "&ROUND(G17,1)&"/100. Remise à niveau URGENTE. Plan d'action immédiat.")))) -> ⏳ Aucune intervention saisie pour cette équipe.
B18: ='👥 ÉQUIPES'!$B$16 -> 0 | C18: =COUNTIF('📋 SAISIE'!$C$7:$C$56,'👥 ÉQUIPES'!$B$16) -> 0 | D18: =IFERROR(ROUND(AVERAGEIF('📋 SAISIE'!$C$7:$C$56,'👥 ÉQUIPES'!$B$16,'📋 SAISIE'!$AB$7:$AB$56),1),"—") -> — | E18: =IFERROR(ROUND(AVERAGEIF('📋 SAISIE'!$C$7:$C$56,'👥 ÉQUIPES'!$B$16,'📋 SAISIE'!$AC$7:$AC$56),1),"—") -> — | F18: =IFERROR(ROUND(AVERAGEIF('📋 SAISIE'!$C$7:$C$56,'👥 ÉQUIPES'!$B$16,'📋 SAISIE'!$AD$7:$AD$56),1),"—") -> — | G18: =IFERROR(ROUND(AVERAGEIF('📋 SAISIE'!$C$7:$C$56,'👥 ÉQUIPES'!$B$16,'📋 SAISIE'!$AE$7:$AE$56),1),"—") -> — | H18: =IF(C18=0,"—",IF(G18>=85,"A",IF(G18>=70,"B",IF(G18>=50,"C","D")))) -> — | I18: =IF(C18=0,"⏳ Aucune intervention saisie pour cette équipe.",IF(G18>=85,"🏆 EXCELLENT – "&B18&" : "&C18&" intervention(s) – Moyenne "&ROUND(G18,1)&"/100. Équipe au top, maintenir le rythme !",IF(G18>=70,"✅ BON NIVEAU – "&B18&" : "&C18&" intervention(s) – Moyenne "&ROUND(G18,1)&"/100. Bon travail, axes d'amélioration ciblés.",IF(G18>=50,"⚠️ PASSABLE – "&B18&" : "&C18&" intervention(s) – Moyenne "&ROUND(G18,1)&"/100. Formation recommandée. Accompagnement renforcé nécessaire.","🚨 INSUFFISANT – "&B18&" : "&C18&" intervention(s) – Moyenne "&ROUND(G18,1)&"/100. Remise à niveau URGENTE. Plan d'action immédiat.")))) -> ⏳ Aucune intervention saisie pour cette équipe.
B19: ='👥 ÉQUIPES'!$B$17 -> 0 | C19: =COUNTIF('📋 SAISIE'!$C$7:$C$56,'👥 ÉQUIPES'!$B$17) -> 0 | D19: =IFERROR(ROUND(AVERAGEIF('📋 SAISIE'!$C$7:$C$56,'👥 ÉQUIPES'!$B$17,'📋 SAISIE'!$AB$7:$AB$56),1),"—") -> — | E19: =IFERROR(ROUND(AVERAGEIF('📋 SAISIE'!$C$7:$C$56,'👥 ÉQUIPES'!$B$17,'📋 SAISIE'!$AC$7:$AC$56),1),"—") -> — | F19: =IFERROR(ROUND(AVERAGEIF('📋 SAISIE'!$C$7:$C$56,'👥 ÉQUIPES'!$B$17,'📋 SAISIE'!$AD$7:$AD$56),1),"—") -> — | G19: =IFERROR(ROUND(AVERAGEIF('📋 SAISIE'!$C$7:$C$56,'👥 ÉQUIPES'!$B$17,'📋 SAISIE'!$AE$7:$AE$56),1),"—") -> — | H19: =IF(C19=0,"—",IF(G19>=85,"A",IF(G19>=70,"B",IF(G19>=50,"C","D")))) -> — | I19: =IF(C19=0,"⏳ Aucune intervention saisie pour cette équipe.",IF(G19>=85,"🏆 EXCELLENT – "&B19&" : "&C19&" intervention(s) – Moyenne "&ROUND(G19,1)&"/100. Équipe au top, maintenir le rythme !",IF(G19>=70,"✅ BON NIVEAU – "&B19&" : "&C19&" intervention(s) – Moyenne "&ROUND(G19,1)&"/100. Bon travail, axes d'amélioration ciblés.",IF(G19>=50,"⚠️ PASSABLE – "&B19&" : "&C19&" intervention(s) – Moyenne "&ROUND(G19,1)&"/100. Formation recommandée. Accompagnement renforcé nécessaire.","🚨 INSUFFISANT – "&B19&" : "&C19&" intervention(s) – Moyenne "&ROUND(G19,1)&"/100. Remise à niveau URGENTE. Plan d'action immédiat.")))) -> ⏳ Aucune intervention saisie pour cette équipe.
B20: ='👥 ÉQUIPES'!$B$18 -> 0 | C20: =COUNTIF('📋 SAISIE'!$C$7:$C$56,'👥 ÉQUIPES'!$B$18) -> 0 | D20: =IFERROR(ROUND(AVERAGEIF('📋 SAISIE'!$C$7:$C$56,'👥 ÉQUIPES'!$B$18,'📋 SAISIE'!$AB$7:$AB$56),1),"—") -> — | E20: =IFERROR(ROUND(AVERAGEIF('📋 SAISIE'!$C$7:$C$56,'👥 ÉQUIPES'!$B$18,'📋 SAISIE'!$AC$7:$AC$56),1),"—") -> — | F20: =IFERROR(ROUND(AVERAGEIF('📋 SAISIE'!$C$7:$C$56,'👥 ÉQUIPES'!$B$18,'📋 SAISIE'!$AD$7:$AD$56),1),"—") -> — | G20: =IFERROR(ROUND(AVERAGEIF('📋 SAISIE'!$C$7:$C$56,'👥 ÉQUIPES'!$B$18,'📋 SAISIE'!$AE$7:$AE$56),1),"—") -> — | H20: =IF(C20=0,"—",IF(G20>=85,"A",IF(G20>=70,"B",IF(G20>=50,"C","D")))) -> — | I20: =IF(C20=0,"⏳ Aucune intervention saisie pour cette équipe.",IF(G20>=85,"🏆 EXCELLENT – "&B20&" : "&C20&" intervention(s) – Moyenne "&ROUND(G20,1)&"/100. Équipe au top, maintenir le rythme !",IF(G20>=70,"✅ BON NIVEAU – "&B20&" : "&C20&" intervention(s) – Moyenne "&ROUND(G20,1)&"/100. Bon travail, axes d'amélioration ciblés.",IF(G20>=50,"⚠️ PASSABLE – "&B20&" : "&C20&" intervention(s) – Moyenne "&ROUND(G20,1)&"/100. Formation recommandée. Accompagnement renforcé nécessaire.","🚨 INSUFFISANT – "&B20&" : "&C20&" intervention(s) – Moyenne "&ROUND(G20,1)&"/100. Remise à niveau URGENTE. Plan d'action immédiat.")))) -> ⏳ Aucune intervention saisie pour cette équipe.
B21: ='👥 ÉQUIPES'!$B$19 -> 0 | C21: =COUNTIF('📋 SAISIE'!$C$7:$C$56,'👥 ÉQUIPES'!$B$19) -> 0 | D21: =IFERROR(ROUND(AVERAGEIF('📋 SAISIE'!$C$7:$C$56,'👥 ÉQUIPES'!$B$19,'📋 SAISIE'!$AB$7:$AB$56),1),"—") -> — | E21: =IFERROR(ROUND(AVERAGEIF('📋 SAISIE'!$C$7:$C$56,'👥 ÉQUIPES'!$B$19,'📋 SAISIE'!$AC$7:$AC$56),1),"—") -> — | F21: =IFERROR(ROUND(AVERAGEIF('📋 SAISIE'!$C$7:$C$56,'👥 ÉQUIPES'!$B$19,'📋 SAISIE'!$AD$7:$AD$56),1),"—") -> — | G21: =IFERROR(ROUND(AVERAGEIF('📋 SAISIE'!$C$7:$C$56,'👥 ÉQUIPES'!$B$19,'📋 SAISIE'!$AE$7:$AE$56),1),"—") -> — | H21: =IF(C21=0,"—",IF(G21>=85,"A",IF(G21>=70,"B",IF(G21>=50,"C","D")))) -> — | I21: =IF(C21=0,"⏳ Aucune intervention saisie pour cette équipe.",IF(G21>=85,"🏆 EXCELLENT – "&B21&" : "&C21&" intervention(s) – Moyenne "&ROUND(G21,1)&"/100. Équipe au top, maintenir le rythme !",IF(G21>=70,"✅ BON NIVEAU – "&B21&" : "&C21&" intervention(s) – Moyenne "&ROUND(G21,1)&"/100. Bon travail, axes d'amélioration ciblés.",IF(G21>=50,"⚠️ PASSABLE – "&B21&" : "&C21&" intervention(s) – Moyenne "&ROUND(G21,1)&"/100. Formation recommandée. Accompagnement renforcé nécessaire.","🚨 INSUFFISANT – "&B21&" : "&C21&" intervention(s) – Moyenne "&ROUND(G21,1)&"/100. Remise à niveau URGENTE. Plan d'action immédiat.")))) -> ⏳ Aucune intervention saisie pour cette équipe.
B22: ='👥 ÉQUIPES'!$B$20 -> 0 | C22: =COUNTIF('📋 SAISIE'!$C$7:$C$56,'👥 ÉQUIPES'!$B$20) -> 0 | D22: =IFERROR(ROUND(AVERAGEIF('📋 SAISIE'!$C$7:$C$56,'👥 ÉQUIPES'!$B$20,'📋 SAISIE'!$AB$7:$AB$56),1),"—") -> — | E22: =IFERROR(ROUND(AVERAGEIF('📋 SAISIE'!$C$7:$C$56,'👥 ÉQUIPES'!$B$20,'📋 SAISIE'!$AC$7:$AC$56),1),"—") -> — | F22: =IFERROR(ROUND(AVERAGEIF('📋 SAISIE'!$C$7:$C$56,'👥 ÉQUIPES'!$B$20,'📋 SAISIE'!$AD$7:$AD$56),1),"—") -> — | G22: =IFERROR(ROUND(AVERAGEIF('📋 SAISIE'!$C$7:$C$56,'👥 ÉQUIPES'!$B$20,'📋 SAISIE'!$AE$7:$AE$56),1),"—") -> — | H22: =IF(C22=0,"—",IF(G22>=85,"A",IF(G22>=70,"B",IF(G22>=50,"C","D")))) -> — | I22: =IF(C22=0,"⏳ Aucune intervention saisie pour cette équipe.",IF(G22>=85,"🏆 EXCELLENT – "&B22&" : "&C22&" intervention(s) – Moyenne "&ROUND(G22,1)&"/100. Équipe au top, maintenir le rythme !",IF(G22>=70,"✅ BON NIVEAU – "&B22&" : "&C22&" intervention(s) – Moyenne "&ROUND(G22,1)&"/100. Bon travail, axes d'amélioration ciblés.",IF(G22>=50,"⚠️ PASSABLE – "&B22&" : "&C22&" intervention(s) – Moyenne "&ROUND(G22,1)&"/100. Formation recommandée. Accompagnement renforcé nécessaire.","🚨 INSUFFISANT – "&B22&" : "&C22&" intervention(s) – Moyenne "&ROUND(G22,1)&"/100. Remise à niveau URGENTE. Plan d'action immédiat.")))) -> ⏳ Aucune intervention saisie pour cette équipe.
B23: ='👥 ÉQUIPES'!$B$21 -> 0 | C23: =COUNTIF('📋 SAISIE'!$C$7:$C$56,'👥 ÉQUIPES'!$B$21) -> 0 | D23: =IFERROR(ROUND(AVERAGEIF('📋 SAISIE'!$C$7:$C$56,'👥 ÉQUIPES'!$B$21,'📋 SAISIE'!$AB$7:$AB$56),1),"—") -> — | E23: =IFERROR(ROUND(AVERAGEIF('📋 SAISIE'!$C$7:$C$56,'👥 ÉQUIPES'!$B$21,'📋 SAISIE'!$AC$7:$AC$56),1),"—") -> — | F23: =IFERROR(ROUND(AVERAGEIF('📋 SAISIE'!$C$7:$C$56,'👥 ÉQUIPES'!$B$21,'📋 SAISIE'!$AD$7:$AD$56),1),"—") -> — | G23: =IFERROR(ROUND(AVERAGEIF('📋 SAISIE'!$C$7:$C$56,'👥 ÉQUIPES'!$B$21,'📋 SAISIE'!$AE$7:$AE$56),1),"—") -> — | H23: =IF(C23=0,"—",IF(G23>=85,"A",IF(G23>=70,"B",IF(G23>=50,"C","D")))) -> — | I23: =IF(C23=0,"⏳ Aucune intervention saisie pour cette équipe.",IF(G23>=85,"🏆 EXCELLENT – "&B23&" : "&C23&" intervention(s) – Moyenne "&ROUND(G23,1)&"/100. Équipe au top, maintenir le rythme !",IF(G23>=70,"✅ BON NIVEAU – "&B23&" : "&C23&" intervention(s) – Moyenne "&ROUND(G23,1)&"/100. Bon travail, axes d'amélioration ciblés.",IF(G23>=50,"⚠️ PASSABLE – "&B23&" : "&C23&" intervention(s) – Moyenne "&ROUND(G23,1)&"/100. Formation recommandée. Accompagnement renforcé nécessaire.","🚨 INSUFFISANT – "&B23&" : "&C23&" intervention(s) – Moyenne "&ROUND(G23,1)&"/100. Remise à niveau URGENTE. Plan d'action immédiat.")))) -> ⏳ Aucune intervention saisie pour cette équipe.
B24: ='👥 ÉQUIPES'!$B$22 -> 0 | C24: =COUNTIF('📋 SAISIE'!$C$7:$C$56,'👥 ÉQUIPES'!$B$22) -> 0 | D24: =IFERROR(ROUND(AVERAGEIF('📋 SAISIE'!$C$7:$C$56,'👥 ÉQUIPES'!$B$22,'📋 SAISIE'!$AB$7:$AB$56),1),"—") -> — | E24: =IFERROR(ROUND(AVERAGEIF('📋 SAISIE'!$C$7:$C$56,'👥 ÉQUIPES'!$B$22,'📋 SAISIE'!$AC$7:$AC$56),1),"—") -> — | F24: =IFERROR(ROUND(AVERAGEIF('📋 SAISIE'!$C$7:$C$56,'👥 ÉQUIPES'!$B$22,'📋 SAISIE'!$AD$7:$AD$56),1),"—") -> — | G24: =IFERROR(ROUND(AVERAGEIF('📋 SAISIE'!$C$7:$C$56,'👥 ÉQUIPES'!$B$22,'📋 SAISIE'!$AE$7:$AE$56),1),"—") -> — | H24: =IF(C24=0,"—",IF(G24>=85,"A",IF(G24>=70,"B",IF(G24>=50,"C","D")))) -> — | I24: =IF(C24=0,"⏳ Aucune intervention saisie pour cette équipe.",IF(G24>=85,"🏆 EXCELLENT – "&B24&" : "&C24&" intervention(s) – Moyenne "&ROUND(G24,1)&"/100. Équipe au top, maintenir le rythme !",IF(G24>=70,"✅ BON NIVEAU – "&B24&" : "&C24&" intervention(s) – Moyenne "&ROUND(G24,1)&"/100. Bon travail, axes d'amélioration ciblés.",IF(G24>=50,"⚠️ PASSABLE – "&B24&" : "&C24&" intervention(s) – Moyenne "&ROUND(G24,1)&"/100. Formation recommandée. Accompagnement renforcé nécessaire.","🚨 INSUFFISANT – "&B24&" : "&C24&" intervention(s) – Moyenne "&ROUND(G24,1)&"/100. Remise à niveau URGENTE. Plan d'action immédiat.")))) -> ⏳ Aucune intervention saisie pour cette équipe.
B25: ='👥 ÉQUIPES'!$B$23 -> 0 | C25: =COUNTIF('📋 SAISIE'!$C$7:$C$56,'👥 ÉQUIPES'!$B$23) -> 0 | D25: =IFERROR(ROUND(AVERAGEIF('📋 SAISIE'!$C$7:$C$56,'👥 ÉQUIPES'!$B$23,'📋 SAISIE'!$AB$7:$AB$56),1),"—") -> — | E25: =IFERROR(ROUND(AVERAGEIF('📋 SAISIE'!$C$7:$C$56,'👥 ÉQUIPES'!$B$23,'📋 SAISIE'!$AC$7:$AC$56),1),"—") -> — | F25: =IFERROR(ROUND(AVERAGEIF('📋 SAISIE'!$C$7:$C$56,'👥 ÉQUIPES'!$B$23,'📋 SAISIE'!$AD$7:$AD$56),1),"—") -> — | G25: =IFERROR(ROUND(AVERAGEIF('📋 SAISIE'!$C$7:$C$56,'👥 ÉQUIPES'!$B$23,'📋 SAISIE'!$AE$7:$AE$56),1),"—") -> — | H25: =IF(C25=0,"—",IF(G25>=85,"A",IF(G25>=70,"B",IF(G25>=50,"C","D")))) -> — | I25: =IF(C25=0,"⏳ Aucune intervention saisie pour cette équipe.",IF(G25>=85,"🏆 EXCELLENT – "&B25&" : "&C25&" intervention(s) – Moyenne "&ROUND(G25,1)&"/100. Équipe au top, maintenir le rythme !",IF(G25>=70,"✅ BON NIVEAU – "&B25&" : "&C25&" intervention(s) – Moyenne "&ROUND(G25,1)&"/100. Bon travail, axes d'amélioration ciblés.",IF(G25>=50,"⚠️ PASSABLE – "&B25&" : "&C25&" intervention(s) – Moyenne "&ROUND(G25,1)&"/100. Formation recommandée. Accompagnement renforcé nécessaire.","🚨 INSUFFISANT – "&B25&" : "&C25&" intervention(s) – Moyenne "&ROUND(G25,1)&"/100. Remise à niveau URGENTE. Plan d'action immédiat.")))) -> ⏳ Aucune intervention saisie pour cette équipe.
B26: ='👥 ÉQUIPES'!$B$24 -> 0 | C26: =COUNTIF('📋 SAISIE'!$C$7:$C$56,'👥 ÉQUIPES'!$B$24) -> 0 | D26: =IFERROR(ROUND(AVERAGEIF('📋 SAISIE'!$C$7:$C$56,'👥 ÉQUIPES'!$B$24,'📋 SAISIE'!$AB$7:$AB$56),1),"—") -> — | E26: =IFERROR(ROUND(AVERAGEIF('📋 SAISIE'!$C$7:$C$56,'👥 ÉQUIPES'!$B$24,'📋 SAISIE'!$AC$7:$AC$56),1),"—") -> — | F26: =IFERROR(ROUND(AVERAGEIF('📋 SAISIE'!$C$7:$C$56,'👥 ÉQUIPES'!$B$24,'📋 SAISIE'!$AD$7:$AD$56),1),"—") -> — | G26: =IFERROR(ROUND(AVERAGEIF('📋 SAISIE'!$C$7:$C$56,'👥 ÉQUIPES'!$B$24,'📋 SAISIE'!$AE$7:$AE$56),1),"—") -> — | H26: =IF(C26=0,"—",IF(G26>=85,"A",IF(G26>=70,"B",IF(G26>=50,"C","D")))) -> — | I26: =IF(C26=0,"⏳ Aucune intervention saisie pour cette équipe.",IF(G26>=85,"🏆 EXCELLENT – "&B26&" : "&C26&" intervention(s) – Moyenne "&ROUND(G26,1)&"/100. Équipe au top, maintenir le rythme !",IF(G26>=70,"✅ BON NIVEAU – "&B26&" : "&C26&" intervention(s) – Moyenne "&ROUND(G26,1)&"/100. Bon travail, axes d'amélioration ciblés.",IF(G26>=50,"⚠️ PASSABLE – "&B26&" : "&C26&" intervention(s) – Moyenne "&ROUND(G26,1)&"/100. Formation recommandée. Accompagnement renforcé nécessaire.","🚨 INSUFFISANT – "&B26&" : "&C26&" intervention(s) – Moyenne "&ROUND(G26,1)&"/100. Remise à niveau URGENTE. Plan d'action immédiat.")))) -> ⏳ Aucune intervention saisie pour cette équipe.

Sheet 📅 SUIVI PAR JOUR
A1: 📅 SUIVI PAR JOUR – ANALYSE QUOTIDIENNE
A2: Saisissez une date dans la colonne B pour voir toutes les interventions de ce jour et la synthèse de l'équipe ce jour-là.
A4: 📅 Filtrer par date : | E4: ← Saisissez une date pour filtrer les interventions de ce jour
A6: SYNTHÈSE DES ÉQUIPES POUR LA DATE SÉLECTIONNÉE
B7: ÉQUIPE | C7: Nb Interv. ce jour | D7: Moy. Terrain/60 | E7: Moy. Comport/50 | F7: Moy. /100 | G7: Niveau Jour | H7: Tendance vs global | I7: VERDICT DU JOUR
B8: ='👥 ÉQUIPES'!$B$5 -> Équipe A | C8: =IF($D$4="","—",COUNTIFS('📋 SAISIE'!$C$7:$C$56,'👥 ÉQUIPES'!$B$5,'📋 SAISIE'!$B$7:$B$56,$D$4)) -> — | D8: =IF($D$4="","—",IFERROR(ROUND(AVERAGEIFS('📋 SAISIE'!$AB$7:$AB$56,'📋 SAISIE'!$C$7:$C$56,'👥 ÉQUIPES'!$B$5,'📋 SAISIE'!$B$7:$B$56,$D$4),1),"—")) -> — | E8: =IF($D$4="","—",IFERROR(ROUND(AVERAGEIFS('📋 SAISIE'!$AC$7:$AC$56,'📋 SAISIE'!$C$7:$C$56,'👥 ÉQUIPES'!$B$5,'📋 SAISIE'!$B$7:$B$56,$D$4),1),"—")) -> — | F8: =IF($D$4="","—",IFERROR(ROUND(AVERAGEIFS('📋 SAISIE'!$AE$7:$AE$56,'📋 SAISIE'!$C$7:$C$56,'👥 ÉQUIPES'!$B$5,'📋 SAISIE'!$B$7:$B$56,$D$4),1),"—")) -> — | G8: =IF(F8="—","—",IF(F8>=85,"A",IF(F8>=70,"B",IF(F8>=50,"C","D")))) -> — | H8: =IF(F8="—","—",IF('📊 TABLEAU DE BORD'!G7="—","—",IF(F8>'📊 TABLEAU DE BORD'!G7,"📈 +"&ROUND(F8-'📊 TABLEAU DE BORD'!G7,1)&" vs moy.",IF(F8<'📊 TABLEAU DE BORD'!G7,"📉 "&ROUND(F8-'📊 TABLEAU DE BORD'!G7,1)&" vs moy.","➡️ = Moy.")))) -> — | I8: =IF(OR(F8="—",C8="—"),"⏳ Sélectionnez une date pour voir le verdict.",IF(C8=0,"⏳ Aucune intervention ce jour pour cette équipe.",IF(F8>=85,"🏆 EXCELLENT – "&B8&" : "&C8&" interv. – Moy "&ROUND(F8,1)&"/100. Équipe au top !",IF(F8>=70,"✅ BON NIVEAU – "&B8&" : "&C8&" interv. – Moy "&ROUND(F8,1)&"/100. Axes d'amélioration ciblés.",IF(F8>=50,"⚠️ PASSABLE – "&B8&" : "&C8&" interv. – Moy "&ROUND(F8,1)&"/100. Formation recommandée.","🚨 INSUFFISANT – "&B8&" : "&C8&" interv. – Moy "&ROUND(F8,1)&"/100. Action URGENTE."))))) -> ⏳ Sélectionnez une date pour voir le verdict.
B9: ='👥 ÉQUIPES'!$B$6 -> Équipe B | C9: =IF($D$4="","—",COUNTIFS('📋 SAISIE'!$C$7:$C$56,'👥 ÉQUIPES'!$B$6,'📋 SAISIE'!$B$7:$B$56,$D$4)) -> — | D9: =IF($D$4="","—",IFERROR(ROUND(AVERAGEIFS('📋 SAISIE'!$AB$7:$AB$56,'📋 SAISIE'!$C$7:$C$56,'👥 ÉQUIPES'!$B$6,'📋 SAISIE'!$B$7:$B$56,$D$4),1),"—")) -> — | E9: =IF($D$4="","—",IFERROR(ROUND(AVERAGEIFS('📋 SAISIE'!$AC$7:$AC$56,'📋 SAISIE'!$C$7:$C$56,'👥 ÉQUIPES'!$B$6,'📋 SAISIE'!$B$7:$B$56,$D$4),1),"—")) -> — | F9: =IF($D$4="","—",IFERROR(ROUND(AVERAGEIFS('📋 SAISIE'!$AE$7:$AE$56,'📋 SAISIE'!$C$7:$C$56,'👥 ÉQUIPES'!$B$6,'📋 SAISIE'!$B$7:$B$56,$D$4),1),"—")) -> — | G9: =IF(F9="—","—",IF(F9>=85,"A",IF(F9>=70,"B",IF(F9>=50,"C","D")))) -> — | H9: =IF(F9="—","—",IF('📊 TABLEAU DE BORD'!G8="—","—",IF(F9>'📊 TABLEAU DE BORD'!G8,"📈 +"&ROUND(F9-'📊 TABLEAU DE BORD'!G8,1)&" vs moy.",IF(F9<'📊 TABLEAU DE BORD'!G8,"📉 "&ROUND(F9-'📊 TABLEAU DE BORD'!G8,1)&" vs moy.","➡️ = Moy.")))) -> — | I9: =IF(OR(F9="—",C9="—"),"⏳ Sélectionnez une date pour voir le verdict.",IF(C9=0,"⏳ Aucune intervention ce jour pour cette équipe.",IF(F9>=85,"🏆 EXCELLENT – "&B9&" : "&C9&" interv. – Moy "&ROUND(F9,1)&"/100. Équipe au top !",IF(F9>=70,"✅ BON NIVEAU – "&B9&" : "&C9&" interv. – Moy "&ROUND(F9,1)&"/100. Axes d'amélioration ciblés.",IF(F9>=50,"⚠️ PASSABLE – "&B9&" : "&C9&" interv. – Moy "&ROUND(F9,1)&"/100. Formation recommandée.","🚨 INSUFFISANT – "&B9&" : "&C9&" interv. – Moy "&ROUND(F9,1)&"/100. Action URGENTE."))))) -> ⏳ Sélectionnez une date pour voir le verdict.
B10: ='👥 ÉQUIPES'!$B$7 -> Équipe C | C10: =IF($D$4="","—",COUNTIFS('📋 SAISIE'!$C$7:$C$56,'👥 ÉQUIPES'!$B$7,'📋 SAISIE'!$B$7:$B$56,$D$4)) -> — | D10: =IF($D$4="","—",IFERROR(ROUND(AVERAGEIFS('📋 SAISIE'!$AB$7:$AB$56,'📋 SAISIE'!$C$7:$C$56,'👥 ÉQUIPES'!$B$7,'📋 SAISIE'!$B$7:$B$56,$D$4),1),"—")) -> — | E10: =IF($D$4="","—",IFERROR(ROUND(AVERAGEIFS('📋 SAISIE'!$AC$7:$AC$56,'📋 SAISIE'!$C$7:$C$56,'👥 ÉQUIPES'!$B$7,'📋 SAISIE'!$B$7:$B$56,$D$4),1),"—")) -> — | F10: =IF($D$4="","—",IFERROR(ROUND(AVERAGEIFS('📋 SAISIE'!$AE$7:$AE$56,'📋 SAISIE'!$C$7:$C$56,'👥 ÉQUIPES'!$B$7,'📋 SAISIE'!$B$7:$B$56,$D$4),1),"—")) -> — | G10: =IF(F10="—","—",IF(F10>=85,"A",IF(F10>=70,"B",IF(F10>=50,"C","D")))) -> — | H10: =IF(F10="—","—",IF('📊 TABLEAU DE BORD'!G9="—","—",IF(F10>'📊 TABLEAU DE BORD'!G9,"📈 +"&ROUND(F10-'📊 TABLEAU DE BORD'!G9,1)&" vs moy.",IF(F10<'📊 TABLEAU DE BORD'!G9,"📉 "&ROUND(F10-'📊 TABLEAU DE BORD'!G9,1)&" vs moy.","➡️ = Moy.")))) -> — | I10: =IF(OR(F10="—",C10="—"),"⏳ Sélectionnez une date pour voir le verdict.",IF(C10=0,"⏳ Aucune intervention ce jour pour cette équipe.",IF(F10>=85,"🏆 EXCELLENT – "&B10&" : "&C10&" interv. – Moy "&ROUND(F10,1)&"/100. Équipe au top !",IF(F10>=70,"✅ BON NIVEAU – "&B10&" : "&C10&" interv. – Moy "&ROUND(F10,1)&"/100. Axes d'amélioration ciblés.",IF(F10>=50,"⚠️ PASSABLE – "&B10&" : "&C10&" interv. – Moy "&ROUND(F10,1)&"/100. Formation recommandée.","🚨 INSUFFISANT – "&B10&" : "&C10&" interv. – Moy "&ROUND(F10,1)&"/100. Action URGENTE."))))) -> ⏳ Sélectionnez une date pour voir le verdict.
B11: ='👥 ÉQUIPES'!$B$8 -> Équipe D | C11: =IF($D$4="","—",COUNTIFS('📋 SAISIE'!$C$7:$C$56,'👥 ÉQUIPES'!$B$8,'📋 SAISIE'!$B$7:$B$56,$D$4)) -> — | D11: =IF($D$4="","—",IFERROR(ROUND(AVERAGEIFS('📋 SAISIE'!$AB$7:$AB$56,'📋 SAISIE'!$C$7:$C$56,'👥 ÉQUIPES'!$B$8,'📋 SAISIE'!$B$7:$B$56,$D$4),1),"—")) -> — | E11: =IF($D$4="","—",IFERROR(ROUND(AVERAGEIFS('📋 SAISIE'!$AC$7:$AC$56,'📋 SAISIE'!$C$7:$C$56,'👥 ÉQUIPES'!$B$8,'📋 SAISIE'!$B$7:$B$56,$D$4),1),"—")) -> — | F11: =IF($D$4="","—",IFERROR(ROUND(AVERAGEIFS('📋 SAISIE'!$AE$7:$AE$56,'📋 SAISIE'!$C$7:$C$56,'👥 ÉQUIPES'!$B$8,'📋 SAISIE'!$B$7:$B$56,$D$4),1),"—")) -> — | G11: =IF(F11="—","—",IF(F11>=85,"A",IF(F11>=70,"B",IF(F11>=50,"C","D")))) -> — | H11: =IF(F11="—","—",IF('📊 TABLEAU DE BORD'!G10="—","—",IF(F11>'📊 TABLEAU DE BORD'!G10,"📈 +"&ROUND(F11-'📊 TABLEAU DE BORD'!G10,1)&" vs moy.",IF(F11<'📊 TABLEAU DE BORD'!G10,"📉 "&ROUND(F11-'📊 TABLEAU DE BORD'!G10,1)&" vs moy.","➡️ = Moy.")))) -> — | I11: =IF(OR(F11="—",C11="—"),"⏳ Sélectionnez une date pour voir le verdict.",IF(C11=0,"⏳ Aucune intervention ce jour pour cette équipe.",IF(F11>=85,"🏆 EXCELLENT – "&B11&" : "&C11&" interv. – Moy "&ROUND(F11,1)&"/100. Équipe au top !",IF(F11>=70,"✅ BON NIVEAU – "&B11&" : "&C11&" interv. – Moy "&ROUND(F11,1)&"/100. Axes d'amélioration ciblés.",IF(F11>=50,"⚠️ PASSABLE – "&B11&" : "&C11&" interv. – Moy "&ROUND(F11,1)&"/100. Formation recommandée.","🚨 INSUFFISANT – "&B11&" : "&C11&" interv. – Moy "&ROUND(F11,1)&"/100. Action URGENTE."))))) -> ⏳ Sélectionnez une date pour voir le verdict.
B12: ='👥 ÉQUIPES'!$B$9 -> Équipe E | C12: =IF($D$4="","—",COUNTIFS('📋 SAISIE'!$C$7:$C$56,'👥 ÉQUIPES'!$B$9,'📋 SAISIE'!$B$7:$B$56,$D$4)) -> — | D12: =IF($D$4="","—",IFERROR(ROUND(AVERAGEIFS('📋 SAISIE'!$AB$7:$AB$56,'📋 SAISIE'!$C$7:$C$56,'👥 ÉQUIPES'!$B$9,'📋 SAISIE'!$B$7:$B$56,$D$4),1),"—")) -> — | E12: =IF($D$4="","—",IFERROR(ROUND(AVERAGEIFS('📋 SAISIE'!$AC$7:$AC$56,'📋 SAISIE'!$C$7:$C$56,'👥 ÉQUIPES'!$B$9,'📋 SAISIE'!$B$7:$B$56,$D$4),1),"—")) -> — | F12: =IF($D$4="","—",IFERROR(ROUND(AVERAGEIFS('📋 SAISIE'!$AE$7:$AE$56,'📋 SAISIE'!$C$7:$C$56,'👥 ÉQUIPES'!$B$9,'📋 SAISIE'!$B$7:$B$56,$D$4),1),"—")) -> — | G12: =IF(F12="—","—",IF(F12>=85,"A",IF(F12>=70,"B",IF(F12>=50,"C","D")))) -> — | H12: =IF(F12="—","—",IF('📊 TABLEAU DE BORD'!G11="—","—",IF(F12>'📊 TABLEAU DE BORD'!G11,"📈 +"&ROUND(F12-'📊 TABLEAU DE BORD'!G11,1)&" vs moy.",IF(F12<'📊 TABLEAU DE BORD'!G11,"📉 "&ROUND(F12-'📊 TABLEAU DE BORD'!G11,1)&" vs moy.","➡️ = Moy.")))) -> — | I12: =IF(OR(F12="—",C12="—"),"⏳ Sélectionnez une date pour voir le verdict.",IF(C12=0,"⏳ Aucune intervention ce jour pour cette équipe.",IF(F12>=85,"🏆 EXCELLENT – "&B12&" : "&C12&" interv. – Moy "&ROUND(F12,1)&"/100. Équipe au top !",IF(F12>=70,"✅ BON NIVEAU – "&B12&" : "&C12&" interv. – Moy "&ROUND(F12,1)&"/100. Axes d'amélioration ciblés.",IF(F12>=50,"⚠️ PASSABLE – "&B12&" : "&C12&" interv. – Moy "&ROUND(F12,1)&"/100. Formation recommandée.","🚨 INSUFFISANT – "&B12&" : "&C12&" interv. – Moy "&ROUND(F12,1)&"/100. Action URGENTE."))))) -> ⏳ Sélectionnez une date pour voir le verdict.
B13: ='👥 ÉQUIPES'!$B$10 -> 0 | C13: =IF($D$4="","—",COUNTIFS('📋 SAISIE'!$C$7:$C$56,'👥 ÉQUIPES'!$B$10,'📋 SAISIE'!$B$7:$B$56,$D$4)) -> — | D13: =IF($D$4="","—",IFERROR(ROUND(AVERAGEIFS('📋 SAISIE'!$AB$7:$AB$56,'📋 SAISIE'!$C$7:$C$56,'👥 ÉQUIPES'!$B$10,'📋 SAISIE'!$B$7:$B$56,$D$4),1),"—")) -> — | E13: =IF($D$4="","—",IFERROR(ROUND(AVERAGEIFS('📋 SAISIE'!$AC$7:$AC$56,'📋 SAISIE'!$C$7:$C$56,'👥 ÉQUIPES'!$B$10,'📋 SAISIE'!$B$7:$B$56,$D$4),1),"—")) -> — | F13: =IF($D$4="","—",IFERROR(ROUND(AVERAGEIFS('📋 SAISIE'!$AE$7:$AE$56,'📋 SAISIE'!$C$7:$C$56,'👥 ÉQUIPES'!$B$10,'📋 SAISIE'!$B$7:$B$56,$D$4),1),"—")) -> — | G13: =IF(F13="—","—",IF(F13>=85,"A",IF(F13>=70,"B",IF(F13>=50,"C","D")))) -> — | H13: =IF(F13="—","—",IF('📊 TABLEAU DE BORD'!G12="—","—",IF(F13>'📊 TABLEAU DE BORD'!G12,"📈 +"&ROUND(F13-'📊 TABLEAU DE BORD'!G12,1)&" vs moy.",IF(F13<'📊 TABLEAU DE BORD'!G12,"📉 "&ROUND(F13-'📊 TABLEAU DE BORD'!G12,1)&" vs moy.","➡️ = Moy.")))) -> — | I13: =IF(OR(F13="—",C13="—"),"⏳ Sélectionnez une date pour voir le verdict.",IF(C13=0,"⏳ Aucune intervention ce jour pour cette équipe.",IF(F13>=85,"🏆 EXCELLENT – "&B13&" : "&C13&" interv. – Moy "&ROUND(F13,1)&"/100. Équipe au top !",IF(F13>=70,"✅ BON NIVEAU – "&B13&" : "&C13&" interv. – Moy "&ROUND(F13,1)&"/100. Axes d'amélioration ciblés.",IF(F13>=50,"⚠️ PASSABLE – "&B13&" : "&C13&" interv. – Moy "&ROUND(F13,1)&"/100. Formation recommandée.","🚨 INSUFFISANT – "&B13&" : "&C13&" interv. – Moy "&ROUND(F13,1)&"/100. Action URGENTE."))))) -> ⏳ Sélectionnez une date pour voir le verdict.
B14: ='👥 ÉQUIPES'!$B$11 -> 0 | C14: =IF($D$4="","—",COUNTIFS('📋 SAISIE'!$C$7:$C$56,'👥 ÉQUIPES'!$B$11,'📋 SAISIE'!$B$7:$B$56,$D$4)) -> — | D14: =IF($D$4="","—",IFERROR(ROUND(AVERAGEIFS('📋 SAISIE'!$AB$7:$AB$56,'📋 SAISIE'!$C$7:$C$56,'👥 ÉQUIPES'!$B$11,'📋 SAISIE'!$B$7:$B$56,$D$4),1),"—")) -> — | E14: =IF($D$4="","—",IFERROR(ROUND(AVERAGEIFS('📋 SAISIE'!$AC$7:$AC$56,'📋 SAISIE'!$C$7:$C$56,'👥 ÉQUIPES'!$B$11,'📋 SAISIE'!$B$7:$B$56,$D$4),1),"—")) -> — | F14: =IF($D$4="","—",IFERROR(ROUND(AVERAGEIFS('📋 SAISIE'!$AE$7:$AE$56,'📋 SAISIE'!$C$7:$C$56,'👥 ÉQUIPES'!$B$11,'📋 SAISIE'!$B$7:$B$56,$D$4),1),"—")) -> — | G14: =IF(F14="—","—",IF(F14>=85,"A",IF(F14>=70,"B",IF(F14>=50,"C","D")))) -> — | H14: =IF(F14="—","—",IF('📊 TABLEAU DE BORD'!G13="—","—",IF(F14>'📊 TABLEAU DE BORD'!G13,"📈 +"&ROUND(F14-'📊 TABLEAU DE BORD'!G13,1)&" vs moy.",IF(F14<'📊 TABLEAU DE BORD'!G13,"📉 "&ROUND(F14-'📊 TABLEAU DE BORD'!G13,1)&" vs moy.","➡️ = Moy.")))) -> — | I14: =IF(OR(F14="—",C14="—"),"⏳ Sélectionnez une date pour voir le verdict.",IF(C14=0,"⏳ Aucune intervention ce jour pour cette équipe.",IF(F14>=85,"🏆 EXCELLENT – "&B14&" : "&C14&" interv. – Moy "&ROUND(F14,1)&"/100. Équipe au top !",IF(F14>=70,"✅ BON NIVEAU – "&B14&" : "&C14&" interv. – Moy "&ROUND(F14,1)&"/100. Axes d'amélioration ciblés.",IF(F14>=50,"⚠️ PASSABLE – "&B14&" : "&C14&" interv. – Moy "&ROUND(F14,1)&"/100. Formation recommandée.","🚨 INSUFFISANT – "&B14&" : "&C14&" interv. – Moy "&ROUND(F14,1)&"/100. Action URGENTE."))))) -> ⏳ Sélectionnez une date pour voir le verdict.
B15: ='👥 ÉQUIPES'!$B$12 -> 0 | C15: =IF($D$4="","—",COUNTIFS('📋 SAISIE'!$C$7:$C$56,'👥 ÉQUIPES'!$B$12,'📋 SAISIE'!$B$7:$B$56,$D$4)) -> — | D15: =IF($D$4="","—",IFERROR(ROUND(AVERAGEIFS('📋 SAISIE'!$AB$7:$AB$56,'📋 SAISIE'!$C$7:$C$56,'👥 ÉQUIPES'!$B$12,'📋 SAISIE'!$B$7:$B$56,$D$4),1),"—")) -> — | E15: =IF($D$4="","—",IFERROR(ROUND(AVERAGEIFS('📋 SAISIE'!$AC$7:$AC$56,'📋 SAISIE'!$C$7:$C$56,'👥 ÉQUIPES'!$B$12,'📋 SAISIE'!$B$7:$B$56,$D$4),1),"—")) -> — | F15: =IF($D$4="","—",IFERROR(ROUND(AVERAGEIFS('📋 SAISIE'!$AE$7:$AE$56,'📋 SAISIE'!$C$7:$C$56,'👥 ÉQUIPES'!$B$12,'📋 SAISIE'!$B$7:$B$56,$D$4),1),"—")) -> — | G15: =IF(F15="—","—",IF(F15>=85,"A",IF(F15>=70,"B",IF(F15>=50,"C","D")))) -> — | H15: =IF(F15="—","—",IF('📊 TABLEAU DE BORD'!G14="—","—",IF(F15>'📊 TABLEAU DE BORD'!G14,"📈 +"&ROUND(F15-'📊 TABLEAU DE BORD'!G14,1)&" vs moy.",IF(F15<'📊 TABLEAU DE BORD'!G14,"📉 "&ROUND(F15-'📊 TABLEAU DE BORD'!G14,1)&" vs moy.","➡️ = Moy.")))) -> — | I15: =IF(OR(F15="—",C15="—"),"⏳ Sélectionnez une date pour voir le verdict.",IF(C15=0,"⏳ Aucune intervention ce jour pour cette équipe.",IF(F15>=85,"🏆 EXCELLENT – "&B15&" : "&C15&" interv. – Moy "&ROUND(F15,1)&"/100. Équipe au top !",IF(F15>=70,"✅ BON NIVEAU – "&B15&" : "&C15&" interv. – Moy "&ROUND(F15,1)&"/100. Axes d'amélioration ciblés.",IF(F15>=50,"⚠️ PASSABLE – "&B15&" : "&C15&" interv. – Moy "&ROUND(F15,1)&"/100. Formation recommandée.","🚨 INSUFFISANT – "&B15&" : "&C15&" interv. – Moy "&ROUND(F15,1)&"/100. Action URGENTE."))))) -> ⏳ Sélectionnez une date pour voir le verdict.
B16: ='👥 ÉQUIPES'!$B$13 -> 0 | C16: =IF($D$4="","—",COUNTIFS('📋 SAISIE'!$C$7:$C$56,'👥 ÉQUIPES'!$B$13,'📋 SAISIE'!$B$7:$B$56,$D$4)) -> — | D16: =IF($D$4="","—",IFERROR(ROUND(AVERAGEIFS('📋 SAISIE'!$AB$7:$AB$56,'📋 SAISIE'!$C$7:$C$56,'👥 ÉQUIPES'!$B$13,'📋 SAISIE'!$B$7:$B$56,$D$4),1),"—")) -> — | E16: =IF($D$4="","—",IFERROR(ROUND(AVERAGEIFS('📋 SAISIE'!$AC$7:$AC$56,'📋 SAISIE'!$C$7:$C$56,'👥 ÉQUIPES'!$B$13,'📋 SAISIE'!$B$7:$B$56,$D$4),1),"—")) -> — | F16: =IF($D$4="","—",IFERROR(ROUND(AVERAGEIFS('📋 SAISIE'!$AE$7:$AE$56,'📋 SAISIE'!$C$7:$C$56,'👥 ÉQUIPES'!$B$13,'📋 SAISIE'!$B$7:$B$56,$D$4),1),"—")) -> — | G16: =IF(F16="—","—",IF(F16>=85,"A",IF(F16>=70,"B",IF(F16>=50,"C","D")))) -> — | H16: =IF(F16="—","—",IF('📊 TABLEAU DE BORD'!G15="—","—",IF(F16>'📊 TABLEAU DE BORD'!G15,"📈 +"&ROUND(F16-'📊 TABLEAU DE BORD'!G15,1)&" vs moy.",IF(F16<'📊 TABLEAU DE BORD'!G15,"📉 "&ROUND(F16-'📊 TABLEAU DE BORD'!G15,1)&" vs moy.","➡️ = Moy.")))) -> — | I16: =IF(OR(F16="—",C16="—"),"⏳ Sélectionnez une date pour voir le verdict.",IF(C16=0,"⏳ Aucune intervention ce jour pour cette équipe.",IF(F16>=85,"🏆 EXCELLENT – "&B16&" : "&C16&" interv. – Moy "&ROUND(F16,1)&"/100. Équipe au top !",IF(F16>=70,"✅ BON NIVEAU – "&B16&" : "&C16&" interv. – Moy "&ROUND(F16,1)&"/100. Axes d'amélioration ciblés.",IF(F16>=50,"⚠️ PASSABLE – "&B16&" : "&C16&" interv. – Moy "&ROUND(F16,1)&"/100. Formation recommandée.","🚨 INSUFFISANT – "&B16&" : "&C16&" interv. – Moy "&ROUND(F16,1)&"/100. Action URGENTE."))))) -> ⏳ Sélectionnez une date pour voir le verdict.
B17: ='👥 ÉQUIPES'!$B$14 -> 0 | C17: =IF($D$4="","—",COUNTIFS('📋 SAISIE'!$C$7:$C$56,'👥 ÉQUIPES'!$B$14,'📋 SAISIE'!$B$7:$B$56,$D$4)) -> — | D17: =IF($D$4="","—",IFERROR(ROUND(AVERAGEIFS('📋 SAISIE'!$AB$7:$AB$56,'📋 SAISIE'!$C$7:$C$56,'👥 ÉQUIPES'!$B$14,'📋 SAISIE'!$B$7:$B$56,$D$4),1),"—")) -> — | E17: =IF($D$4="","—",IFERROR(ROUND(AVERAGEIFS('📋 SAISIE'!$AC$7:$AC$56,'📋 SAISIE'!$C$7:$C$56,'👥 ÉQUIPES'!$B$14,'📋 SAISIE'!$B$7:$B$56,$D$4),1),"—")) -> — | F17: =IF($D$4="","—",IFERROR(ROUND(AVERAGEIFS('📋 SAISIE'!$AE$7:$AE$56,'📋 SAISIE'!$C$7:$C$56,'👥 ÉQUIPES'!$B$14,'📋 SAISIE'!$B$7:$B$56,$D$4),1),"—")) -> — | G17: =IF(F17="—","—",IF(F17>=85,"A",IF(F17>=70,"B",IF(F17>=50,"C","D")))) -> — | H17: =IF(F17="—","—",IF('📊 TABLEAU DE BORD'!G16="—","—",IF(F17>'📊 TABLEAU DE BORD'!G16,"📈 +"&ROUND(F17-'📊 TABLEAU DE BORD'!G16,1)&" vs moy.",IF(F17<'📊 TABLEAU DE BORD'!G16,"📉 "&ROUND(F17-'📊 TABLEAU DE BORD'!G16,1)&" vs moy.","➡️ = Moy.")))) -> — | I17: =IF(OR(F17="—",C17="—"),"⏳ Sélectionnez une date pour voir le verdict.",IF(C17=0,"⏳ Aucune intervention ce jour pour cette équipe.",IF(F17>=85,"🏆 EXCELLENT – "&B17&" : "&C17&" interv. – Moy "&ROUND(F17,1)&"/100. Équipe au top !",IF(F17>=70,"✅ BON NIVEAU – "&B17&" : "&C17&" interv. – Moy "&ROUND(F17,1)&"/100. Axes d'amélioration ciblés.",IF(F17>=50,"⚠️ PASSABLE – "&B17&" : "&C17&" interv. – Moy "&ROUND(F17,1)&"/100. Formation recommandée.","🚨 INSUFFISANT – "&B17&" : "&C17&" interv. – Moy "&ROUND(F17,1)&"/100. Action URGENTE."))))) -> ⏳ Sélectionnez une date pour voir le verdict.
B18: ='👥 ÉQUIPES'!$B$15 -> 0 | C18: =IF($D$4="","—",COUNTIFS('📋 SAISIE'!$C$7:$C$56,'👥 ÉQUIPES'!$B$15,'📋 SAISIE'!$B$7:$B$56,$D$4)) -> — | D18: =IF($D$4="","—",IFERROR(ROUND(AVERAGEIFS('📋 SAISIE'!$AB$7:$AB$56,'📋 SAISIE'!$C$7:$C$56,'👥 ÉQUIPES'!$B$15,'📋 SAISIE'!$B$7:$B$56,$D$4),1),"—")) -> — | E18: =IF($D$4="","—",IFERROR(ROUND(AVERAGEIFS('📋 SAISIE'!$AC$7:$AC$56,'📋 SAISIE'!$C$7:$C$56,'👥 ÉQUIPES'!$B$15,'📋 SAISIE'!$B$7:$B$56,$D$4),1),"—")) -> — | F18: =IF($D$4="","—",IFERROR(ROUND(AVERAGEIFS('📋 SAISIE'!$AE$7:$AE$56,'📋 SAISIE'!$C$7:$C$56,'👥 ÉQUIPES'!$B$15,'📋 SAISIE'!$B$7:$B$56,$D$4),1),"—")) -> — | G18: =IF(F18="—","—",IF(F18>=85,"A",IF(F18>=70,"B",IF(F18>=50,"C","D")))) -> — | H18: =IF(F18="—","—",IF('📊 TABLEAU DE BORD'!G17="—","—",IF(F18>'📊 TABLEAU DE BORD'!G17,"📈 +"&ROUND(F18-'📊 TABLEAU DE BORD'!G17,1)&" vs moy.",IF(F18<'📊 TABLEAU DE BORD'!G17,"📉 "&ROUND(F18-'📊 TABLEAU DE BORD'!G17,1)&" vs moy.","➡️ = Moy.")))) -> — | I18: =IF(OR(F18="—",C18="—"),"⏳ Sélectionnez une date pour voir le verdict.",IF(C18=0,"⏳ Aucune intervention ce jour pour cette équipe.",IF(F18>=85,"🏆 EXCELLENT – "&B18&" : "&C18&" interv. – Moy "&ROUND(F18,1)&"/100. Équipe au top !",IF(F18>=70,"✅ BON NIVEAU – "&B18&" : "&C18&" interv. – Moy "&ROUND(F18,1)&"/100. Axes d'amélioration ciblés.",IF(F18>=50,"⚠️ PASSABLE – "&B18&" : "&C18&" interv. – Moy "&ROUND(F18,1)&"/100. Formation recommandée.","🚨 INSUFFISANT – "&B18&" : "&C18&" interv. – Moy "&ROUND(F18,1)&"/100. Action URGENTE."))))) -> ⏳ Sélectionnez une date pour voir le verdict.
B19: ='👥 ÉQUIPES'!$B$16 -> 0 | C19: =IF($D$4="","—",COUNTIFS('📋 SAISIE'!$C$7:$C$56,'👥 ÉQUIPES'!$B$16,'📋 SAISIE'!$B$7:$B$56,$D$4)) -> — | D19: =IF($D$4="","—",IFERROR(ROUND(AVERAGEIFS('📋 SAISIE'!$AB$7:$AB$56,'📋 SAISIE'!$C$7:$C$56,'👥 ÉQUIPES'!$B$16,'📋 SAISIE'!$B$7:$B$56,$D$4),1),"—")) -> — | E19: =IF($D$4="","—",IFERROR(ROUND(AVERAGEIFS('📋 SAISIE'!$AC$7:$AC$56,'📋 SAISIE'!$C$7:$C$56,'👥 ÉQUIPES'!$B$16,'📋 SAISIE'!$B$7:$B$56,$D$4),1),"—")) -> — | F19: =IF($D$4="","—",IFERROR(ROUND(AVERAGEIFS('📋 SAISIE'!$AE$7:$AE$56,'📋 SAISIE'!$C$7:$C$56,'👥 ÉQUIPES'!$B$16,'📋 SAISIE'!$B$7:$B$56,$D$4),1),"—")) -> — | G19: =IF(F19="—","—",IF(F19>=85,"A",IF(F19>=70,"B",IF(F19>=50,"C","D")))) -> — | H19: =IF(F19="—","—",IF('📊 TABLEAU DE BORD'!G18="—","—",IF(F19>'📊 TABLEAU DE BORD'!G18,"📈 +"&ROUND(F19-'📊 TABLEAU DE BORD'!G18,1)&" vs moy.",IF(F19<'📊 TABLEAU DE BORD'!G18,"📉 "&ROUND(F19-'📊 TABLEAU DE BORD'!G18,1)&" vs moy.","➡️ = Moy.")))) -> — | I19: =IF(OR(F19="—",C19="—"),"⏳ Sélectionnez une date pour voir le verdict.",IF(C19=0,"⏳ Aucune intervention ce jour pour cette équipe.",IF(F19>=85,"🏆 EXCELLENT – "&B19&" : "&C19&" interv. – Moy "&ROUND(F19,1)&"/100. Équipe au top !",IF(F19>=70,"✅ BON NIVEAU – "&B19&" : "&C19&" interv. – Moy "&ROUND(F19,1)&"/100. Axes d'amélioration ciblés.",IF(F19>=50,"⚠️ PASSABLE – "&B19&" : "&C19&" interv. – Moy "&ROUND(F19,1)&"/100. Formation recommandée.","🚨 INSUFFISANT – "&B19&" : "&C19&" interv. – Moy "&ROUND(F19,1)&"/100. Action URGENTE."))))) -> ⏳ Sélectionnez une date pour voir le verdict.
B20: ='👥 ÉQUIPES'!$B$17 -> 0 | C20: =IF($D$4="","—",COUNTIFS('📋 SAISIE'!$C$7:$C$56,'👥 ÉQUIPES'!$B$17,'📋 SAISIE'!$B$7:$B$56,$D$4)) -> — | D20: =IF($D$4="","—",IFERROR(ROUND(AVERAGEIFS('📋 SAISIE'!$AB$7:$AB$56,'📋 SAISIE'!$C$7:$C$56,'👥 ÉQUIPES'!$B$17,'📋 SAISIE'!$B$7:$B$56,$D$4),1),"—")) -> — | E20: =IF($D$4="","—",IFERROR(ROUND(AVERAGEIFS('📋 SAISIE'!$AC$7:$AC$56,'📋 SAISIE'!$C$7:$C$56,'👥 ÉQUIPES'!$B$17,'📋 SAISIE'!$B$7:$B$56,$D$4),1),"—")) -> — | F20: =IF($D$4="","—",IFERROR(ROUND(AVERAGEIFS('📋 SAISIE'!$AE$7:$AE$56,'📋 SAISIE'!$C$7:$C$56,'👥 ÉQUIPES'!$B$17,'📋 SAISIE'!$B$7:$B$56,$D$4),1),"—")) -> — | G20: =IF(F20="—","—",IF(F20>=85,"A",IF(F20>=70,"B",IF(F20>=50,"C","D")))) -> — | H20: =IF(F20="—","—",IF('📊 TABLEAU DE BORD'!G19="—","—",IF(F20>'📊 TABLEAU DE BORD'!G19,"📈 +"&ROUND(F20-'📊 TABLEAU DE BORD'!G19,1)&" vs moy.",IF(F20<'📊 TABLEAU DE BORD'!G19,"📉 "&ROUND(F20-'📊 TABLEAU DE BORD'!G19,1)&" vs moy.","➡️ = Moy.")))) -> — | I20: =IF(OR(F20="—",C20="—"),"⏳ Sélectionnez une date pour voir le verdict.",IF(C20=0,"⏳ Aucune intervention ce jour pour cette équipe.",IF(F20>=85,"🏆 EXCELLENT – "&B20&" : "&C20&" interv. – Moy "&ROUND(F20,1)&"/100. Équipe au top !",IF(F20>=70,"✅ BON NIVEAU – "&B20&" : "&C20&" interv. – Moy "&ROUND(F20,1)&"/100. Axes d'amélioration ciblés.",IF(F20>=50,"⚠️ PASSABLE – "&B20&" : "&C20&" interv. – Moy "&ROUND(F20,1)&"/100. Formation recommandée.","🚨 INSUFFISANT – "&B20&" : "&C20&" interv. – Moy "&ROUND(F20,1)&"/100. Action URGENTE."))))) -> ⏳ Sélectionnez une date pour voir le verdict.
B21: ='👥 ÉQUIPES'!$B$18 -> 0 | C21: =IF($D$4="","—",COUNTIFS('📋 SAISIE'!$C$7:$C$56,'👥 ÉQUIPES'!$B$18,'📋 SAISIE'!$B$7:$B$56,$D$4)) -> — | D21: =IF($D$4="","—",IFERROR(ROUND(AVERAGEIFS('📋 SAISIE'!$AB$7:$AB$56,'📋 SAISIE'!$C$7:$C$56,'👥 ÉQUIPES'!$B$18,'📋 SAISIE'!$B$7:$B$56,$D$4),1),"—")) -> — | E21: =IF($D$4="","—",IFERROR(ROUND(AVERAGEIFS('📋 SAISIE'!$AC$7:$AC$56,'📋 SAISIE'!$C$7:$C$56,'👥 ÉQUIPES'!$B$18,'📋 SAISIE'!$B$7:$B$56,$D$4),1),"—")) -> — | F21: =IF($D$4="","—",IFERROR(ROUND(AVERAGEIFS('📋 SAISIE'!$AE$7:$AE$56,'📋 SAISIE'!$C$7:$C$56,'👥 ÉQUIPES'!$B$18,'📋 SAISIE'!$B$7:$B$56,$D$4),1),"—")) -> — | G21: =IF(F21="—","—",IF(F21>=85,"A",IF(F21>=70,"B",IF(F21>=50,"C","D")))) -> — | H21: =IF(F21="—","—",IF('📊 TABLEAU DE BORD'!G20="—","—",IF(F21>'📊 TABLEAU DE BORD'!G20,"📈 +"&ROUND(F21-'📊 TABLEAU DE BORD'!G20,1)&" vs moy.",IF(F21<'📊 TABLEAU DE BORD'!G20,"📉 "&ROUND(F21-'📊 TABLEAU DE BORD'!G20,1)&" vs moy.","➡️ = Moy.")))) -> — | I21: =IF(OR(F21="—",C21="—"),"⏳ Sélectionnez une date pour voir le verdict.",IF(C21=0,"⏳ Aucune intervention ce jour pour cette équipe.",IF(F21>=85,"🏆 EXCELLENT – "&B21&" : "&C21&" interv. – Moy "&ROUND(F21,1)&"/100. Équipe au top !",IF(F21>=70,"✅ BON NIVEAU – "&B21&" : "&C21&" interv. – Moy "&ROUND(F21,1)&"/100. Axes d'amélioration ciblés.",IF(F21>=50,"⚠️ PASSABLE – "&B21&" : "&C21&" interv. – Moy "&ROUND(F21,1)&"/100. Formation recommandée.","🚨 INSUFFISANT – "&B21&" : "&C21&" interv. – Moy "&ROUND(F21,1)&"/100. Action URGENTE."))))) -> ⏳ Sélectionnez une date pour voir le verdict.
